<?xml version='1.0' encoding='utf-8'?>
<robot name="complete_robotic_arm_assembly_with_dual_manipulator_140mm_shank">
    <link name="28byj_48_5v_stepper_motor">
        <inertial>
            <mass value="1.29383e-05" />
            <origin xyz="4.81215e-08 0.00903231 -0.000985167" rpy="0 -0 0" />
            <inertia ixx="1.21271e-09" ixy="-6.17404e-15" ixz="2.99318e-15" iyy="1.40051e-09" iyz="1.35666e-11" izz="1.03166e-09" />
        </inertial>
        <visual>
            <origin xyz="0 0 0" rpy="0 -0 0" />
            <geometry>
                <mesh filename="../meshes/28byj_48_5v_stepper_motor.stl" scale="1 1 1" />
            </geometry>
            <material name="0.662745_0.686275_0.698039_0.000000_0.000000">
                <texture />
                <color rgba="0.662745 0.686275 0.698039 1" />
            </material>
        </visual>
    <collision><origin xyz="0 0 0" rpy="0 -0 0" /><geometry>
                <mesh filename="../meshes/28byj_48_5v_stepper_motor.stl" scale="1 1 1" />
            </geometry></collision></link>
    <link name="f624zz_103">
        <inertial>
            <mass value="2.52711e-07" />
            <origin xyz="-0.00115244 4.71345e-19 2.39522e-19" rpy="0 -0 0" />
            <inertia ixx="9.55574e-12" ixy="0" ixz="0" iyy="5.35879e-12" iyz="0" izz="5.35879e-12" />
        </inertial>
        <visual>
            <origin xyz="-0.004 0 0" rpy="0 -0 0" />
            <geometry>
                <mesh filename="../meshes/f624zz_90.stl" scale="1 1 1" />
            </geometry>
            <material name="0.792157_0.819608_0.933333_0.000000_0.000000">
                <texture />
                <color rgba="0.792157 0.819608 0.933333 1" />
            </material>
        </visual>
    <collision><origin xyz="-0.004 0 0" rpy="0 -0 0" /><geometry>
                <mesh filename="../meshes/f624zz_90.stl" scale="1 1 1" />
            </geometry></collision></link>
    <link name="f624zz_14">
        <inertial>
            <mass value="2.52711e-07" />
            <origin xyz="-0.00115244 4.71345e-19 2.39522e-19" rpy="0 -0 0" />
            <inertia ixx="9.55574e-12" ixy="0" ixz="0" iyy="5.35879e-12" iyz="0" izz="5.35879e-12" />
        </inertial>
        <visual>
            <origin xyz="-0.004 0 0" rpy="0 -0 0" />
            <geometry>
                <mesh filename="../meshes/f624zz_90.stl" scale="1 1 1" />
            </geometry>
            <material name="0.792157_0.819608_0.933333_0.000000_0.000000">
                <texture />
                <color rgba="0.792157 0.819608 0.933333 1" />
            </material>
        </visual>
    <collision><origin xyz="-0.004 0 0" rpy="0 -0 0" /><geometry>
                <mesh filename="../meshes/f624zz_90.stl" scale="1 1 1" />
            </geometry></collision></link>
    <link name="f624zz_23">
        <inertial>
            <mass value="2.52711e-07" />
            <origin xyz="-0.00115244 4.71345e-19 2.39522e-19" rpy="0 -0 0" />
            <inertia ixx="9.55574e-12" ixy="0" ixz="0" iyy="5.35879e-12" iyz="0" izz="5.35879e-12" />
        </inertial>
        <visual>
            <origin xyz="-0.004 0 0" rpy="0 -0 0" />
            <geometry>
                <mesh filename="../meshes/f624zz_90.stl" scale="1 1 1" />
            </geometry>
            <material name="0.792157_0.819608_0.933333_0.000000_0.000000">
                <texture />
                <color rgba="0.792157 0.819608 0.933333 1" />
            </material>
        </visual>
    <collision><origin xyz="-0.004 0 0" rpy="0 -0 0" /><geometry>
                <mesh filename="../meshes/f624zz_90.stl" scale="1 1 1" />
            </geometry></collision></link>
    <link name="f624zz_34">
        <inertial>
            <mass value="2.52711e-07" />
            <origin xyz="-0.00115244 4.71345e-19 2.39522e-19" rpy="0 -0 0" />
            <inertia ixx="9.55574e-12" ixy="0" ixz="0" iyy="5.35879e-12" iyz="0" izz="5.35879e-12" />
        </inertial>
        <visual>
            <origin xyz="-0.004 0 0" rpy="0 -0 0" />
            <geometry>
                <mesh filename="../meshes/f624zz_90.stl" scale="1 1 1" />
            </geometry>
            <material name="0.792157_0.819608_0.933333_0.000000_0.000000">
                <texture />
                <color rgba="0.792157 0.819608 0.933333 1" />
            </material>
        </visual>
    <collision><origin xyz="-0.004 0 0" rpy="0 -0 0" /><geometry>
                <mesh filename="../meshes/f624zz_90.stl" scale="1 1 1" />
            </geometry></collision></link>
    <link name="f624zz_46">
        <inertial>
            <mass value="2.52711e-07" />
            <origin xyz="-0.00115244 4.71345e-19 2.39522e-19" rpy="0 -0 0" />
            <inertia ixx="9.55574e-12" ixy="0" ixz="0" iyy="5.35879e-12" iyz="0" izz="5.35879e-12" />
        </inertial>
        <visual>
            <origin xyz="-0.004 0 0" rpy="0 -0 0" />
            <geometry>
                <mesh filename="../meshes/f624zz_90.stl" scale="1 1 1" />
            </geometry>
            <material name="0.792157_0.819608_0.933333_0.000000_0.000000">
                <texture />
                <color rgba="0.792157 0.819608 0.933333 1" />
            </material>
        </visual>
    <collision><origin xyz="-0.004 0 0" rpy="0 -0 0" /><geometry>
                <mesh filename="../meshes/f624zz_90.stl" scale="1 1 1" />
            </geometry></collision></link>
    <link name="f624zz_5">
        <inertial>
            <mass value="2.52711e-07" />
            <origin xyz="-0.00115244 4.71345e-19 2.39522e-19" rpy="0 -0 0" />
            <inertia ixx="9.55574e-12" ixy="0" ixz="0" iyy="5.35879e-12" iyz="0" izz="5.35879e-12" />
        </inertial>
        <visual>
            <origin xyz="-0.004 0 0" rpy="0 -0 0" />
            <geometry>
                <mesh filename="../meshes/f624zz_90.stl" scale="1 1 1" />
            </geometry>
            <material name="0.792157_0.819608_0.933333_0.000000_0.000000">
                <texture />
                <color rgba="0.792157 0.819608 0.933333 1" />
            </material>
        </visual>
    <collision><origin xyz="-0.004 0 0" rpy="0 -0 0" /><geometry>
                <mesh filename="../meshes/f624zz_90.stl" scale="1 1 1" />
            </geometry></collision></link>
    <link name="f624zz_55">
        <inertial>
            <mass value="2.52711e-07" />
            <origin xyz="-0.00115244 4.71345e-19 2.39522e-19" rpy="0 -0 0" />
            <inertia ixx="9.55574e-12" ixy="0" ixz="0" iyy="5.35879e-12" iyz="0" izz="5.35879e-12" />
        </inertial>
        <visual>
            <origin xyz="-0.004 0 0" rpy="0 -0 0" />
            <geometry>
                <mesh filename="../meshes/f624zz_90.stl" scale="1 1 1" />
            </geometry>
            <material name="0.792157_0.819608_0.933333_0.000000_0.000000">
                <texture />
                <color rgba="0.792157 0.819608 0.933333 1" />
            </material>
        </visual>
    <collision><origin xyz="-0.004 0 0" rpy="0 -0 0" /><geometry>
                <mesh filename="../meshes/f624zz_90.stl" scale="1 1 1" />
            </geometry></collision></link>
    <link name="f624zz_73">
        <inertial>
            <mass value="2.52711e-07" />
            <origin xyz="-0.00115244 4.71345e-19 2.39522e-19" rpy="0 -0 0" />
            <inertia ixx="9.55574e-12" ixy="0" ixz="0" iyy="5.35879e-12" iyz="0" izz="5.35879e-12" />
        </inertial>
        <visual>
            <origin xyz="-0.004 0 0" rpy="0 -0 0" />
            <geometry>
                <mesh filename="../meshes/f624zz_90.stl" scale="1 1 1" />
            </geometry>
            <material name="0.792157_0.819608_0.933333_0.000000_0.000000">
                <texture />
                <color rgba="0.792157 0.819608 0.933333 1" />
            </material>
        </visual>
    <collision><origin xyz="-0.004 0 0" rpy="0 -0 0" /><geometry>
                <mesh filename="../meshes/f624zz_90.stl" scale="1 1 1" />
            </geometry></collision></link>
    <link name="f624zz_78">
        <inertial>
            <mass value="2.52711e-07" />
            <origin xyz="-0.00115244 4.71345e-19 2.39522e-19" rpy="0 -0 0" />
            <inertia ixx="9.55574e-12" ixy="0" ixz="0" iyy="5.35879e-12" iyz="0" izz="5.35879e-12" />
        </inertial>
        <visual>
            <origin xyz="-0.004 0 0" rpy="0 -0 0" />
            <geometry>
                <mesh filename="../meshes/f624zz_90.stl" scale="1 1 1" />
            </geometry>
            <material name="0.792157_0.819608_0.933333_0.000000_0.000000">
                <texture />
                <color rgba="0.792157 0.819608 0.933333 1" />
            </material>
        </visual>
    <collision><origin xyz="-0.004 0 0" rpy="0 -0 0" /><geometry>
                <mesh filename="../meshes/f624zz_90.stl" scale="1 1 1" />
            </geometry></collision></link>
    <link name="f624zz_90">
        <inertial>
            <mass value="2.52711e-07" />
            <origin xyz="-0.00115244 4.71345e-19 2.39522e-19" rpy="0 -0 0" />
            <inertia ixx="9.55574e-12" ixy="0" ixz="0" iyy="5.35879e-12" iyz="0" izz="5.35879e-12" />
        </inertial>
        <visual>
            <origin xyz="-0.004 0 0" rpy="0 -0 0" />
            <geometry>
                <mesh filename="../meshes/f624zz_90.stl" scale="1 1 1" />
            </geometry>
            <material name="0.792157_0.819608_0.933333_0.000000_0.000000">
                <texture />
                <color rgba="0.792157 0.819608 0.933333 1" />
            </material>
        </visual>
    <collision><origin xyz="-0.004 0 0" rpy="0 -0 0" /><geometry>
                <mesh filename="../meshes/f624zz_90.stl" scale="1 1 1" />
            </geometry></collision></link>
    <link name="f686zz_83">
        <inertial>
            <mass value="2.83426e-07" />
            <origin xyz="0.00283286 8.67362e-19 -1.73472e-18" rpy="0 -0 0" />
            <inertia ixx="1.0476e-11" ixy="0" ixz="0" iyy="5.95232e-12" iyz="0" izz="5.95232e-12" />
        </inertial>
        <visual>
            <origin xyz="0.00881922 -0.00140526 0.0105052" rpy="0 -0 0" />
            <geometry>
                <mesh filename="../meshes/f686zz_83.stl" scale="1 1 1" />
            </geometry>
            <material name="0.792157_0.819608_0.933333_0.000000_0.000000">
                <texture />
                <color rgba="0.792157 0.819608 0.933333 1" />
            </material>
        </visual>
    <collision><origin xyz="0.00881922 -0.00140526 0.0105052" rpy="0 -0 0" /><geometry>
                <mesh filename="../meshes/f686zz_83.stl" scale="1 1 1" />
            </geometry></collision></link>
    <link name="gripper_finger_washer___mymod">
        <inertial>
            <mass value="2.57418e-07" />
            <origin xyz="-0.174337 -0.0267358 0.001" rpy="0 -0 0" />
            <inertia ixx="4.39971e-12" ixy="7.29752e-14" ixz="0" iyy="2.49124e-12" iyz="0" izz="6.71933e-12" />
        </inertial>
        <visual>
            <origin xyz="0 0 0" rpy="0 -0 0" />
            <geometry>
                <mesh filename="../meshes/gripper_finger_washer___mymod_1.stl" scale="1 1 1" />
            </geometry>
            <material name="0.909804_0.443137_0.031373_0.000000_0.000000">
                <texture />
                <color rgba="0.909804 0.443137 0.0313726 1" />
            </material>
        </visual>
    <collision><origin xyz="0 0 0" rpy="0 -0 0" /><geometry>
                <mesh filename="../meshes/gripper_finger_washer___mymod_1.stl" scale="1 1 1" />
            </geometry></collision></link>
    <link name="gripper_finger_washer___mymod_1">
        <inertial>
            <mass value="2.57418e-07" />
            <origin xyz="-0.174337 -0.0267358 0.001" rpy="0 -0 0" />
            <inertia ixx="4.39971e-12" ixy="7.29752e-14" ixz="0" iyy="2.49124e-12" iyz="0" izz="6.71933e-12" />
        </inertial>
        <visual>
            <origin xyz="0 0 0" rpy="0 -0 0" />
            <geometry>
                <mesh filename="../meshes/gripper_finger_washer___mymod_1.stl" scale="1 1 1" />
            </geometry>
            <material name="0.909804_0.443137_0.031373_0.000000_0.000000">
                <texture />
                <color rgba="0.909804 0.443137 0.0313726 1" />
            </material>
        </visual>
    <collision><origin xyz="0 0 0" rpy="0 -0 0" /><geometry>
                <mesh filename="../meshes/gripper_finger_washer___mymod_1.stl" scale="1 1 1" />
            </geometry></collision></link>
    <link name="gripper_fingers_link_wire">
        <inertial>
            <mass value="5.2548e-08" />
            <origin xyz="0.169527 -0.0389644 0.194151" rpy="0 -0 0" />
            <inertia ixx="2.50352e-12" ixy="-1.25961e-12" ixz="0" iyy="7.7235e-13" iyz="0" izz="3.07149e-12" />
        </inertial>
        <visual>
            <origin xyz="0 0 0" rpy="0 -0 0" />
            <geometry>
                <mesh filename="../meshes/gripper_fingers_link_wire_1.stl" scale="1 1 1" />
            </geometry>
            <material name="0.780392_0.760784_0.741176_0.000000_0.000000">
                <texture />
                <color rgba="0.780392 0.760784 0.741176 1" />
            </material>
        </visual>
    <collision><origin xyz="0 0 0" rpy="0 -0 0" /><geometry>
                <mesh filename="../meshes/gripper_fingers_link_wire_1.stl" scale="1 1 1" />
            </geometry></collision></link>
    <link name="gripper_fingers_link_wire_1">
        <inertial>
            <mass value="5.2548e-08" />
            <origin xyz="0.169527 -0.0389644 0.194151" rpy="0 -0 0" />
            <inertia ixx="2.50352e-12" ixy="-1.25961e-12" ixz="0" iyy="7.7235e-13" iyz="0" izz="3.07149e-12" />
        </inertial>
        <visual>
            <origin xyz="0 0 0" rpy="0 -0 0" />
            <geometry>
                <mesh filename="../meshes/gripper_fingers_link_wire_1.stl" scale="1 1 1" />
            </geometry>
            <material name="0.780392_0.760784_0.741176_0.000000_0.000000">
                <texture />
                <color rgba="0.780392 0.760784 0.741176 1" />
            </material>
        </visual>
    <collision><origin xyz="0 0 0" rpy="0 -0 0" /><geometry>
                <mesh filename="../meshes/gripper_fingers_link_wire_1.stl" scale="1 1 1" />
            </geometry></collision></link>
    <link name="gripper_shaft">
        <inertial>
            <mass value="1.7657e-06" />
            <origin xyz="0.172541 -0.0495 0.198272" rpy="0 -0 0" />
            <inertia ixx="4.86296e-11" ixy="0" ixz="0" iyy="4.86296e-11" iyz="0" izz="7.95991e-11" />
        </inertial>
        <visual>
            <origin xyz="0 0 0" rpy="0 -0 0" />
            <geometry>
                <mesh filename="../meshes/gripper_shaft.stl" scale="1 1 1" />
            </geometry>
            <material name="0.298039_0.298039_0.298039_0.000000_0.000000">
                <texture />
                <color rgba="0.298039 0.298039 0.298039 1" />
            </material>
        </visual>
    <collision><origin xyz="0 0 0" rpy="0 -0 0" /><geometry>
                <mesh filename="../meshes/gripper_shaft.stl" scale="1 1 1" />
            </geometry></collision></link>
    <link name="gripperbase_by_ftobler">
        <inertial>
            <mass value="1.98957e-05" />
            <origin xyz="0.0185505 -2.74963e-12 0.00576395" rpy="0 -0 0" />
            <inertia ixx="5.56859e-09" ixy="0" ixz="-1.29708e-10" iyy="4.59113e-09" iyz="0" izz="9.8576e-09" />
        </inertial>
        <visual>
            <origin xyz="-0.145541 0.0495 -0.195348" rpy="0 -0 0" />
            <geometry>
                <mesh filename="../meshes/gripperbase_by_ftobler.stl" scale="1 1 1" />
            </geometry>
            <material name="0.909804_0.443137_0.031373_0.000000_0.000000">
                <texture />
                <color rgba="0.909804 0.443137 0.0313726 1" />
            </material>
        </visual>
    <collision><origin xyz="-0.145541 0.0495 -0.195348" rpy="0 -0 0" /><geometry>
                <mesh filename="../meshes/gripperbase_by_ftobler.stl" scale="1 1 1" />
            </geometry></collision></link>
    <link name="gripperfinger_by_ftobler">
        <inertial>
            <mass value="6.4034e-06" />
            <origin xyz="0.172227 -0.0306439 0.190577" rpy="0 -0 0" />
            <inertia ixx="8.20348e-10" ixy="2.31178e-12" ixz="1.54025e-12" iyy="5.89535e-10" iyz="-2.75788e-10" izz="8.30458e-10" />
        </inertial>
        <visual>
            <origin xyz="0 0 0" rpy="0 -0 0" />
            <geometry>
                <mesh filename="../meshes/gripperfinger_by_ftobler_1.stl" scale="1 1 1" />
            </geometry>
            <material name="0.298039_0.298039_0.298039_0.000000_0.000000">
                <texture />
                <color rgba="0.298039 0.298039 0.298039 1" />
            </material>
        </visual>
    <collision><origin xyz="0 0 0" rpy="0 -0 0" /><geometry>
                <mesh filename="../meshes/gripperfinger_by_ftobler_1.stl" scale="1 1 1" />
            </geometry></collision></link>
    <link name="gripperfinger_by_ftobler_1">
        <inertial>
            <mass value="6.4034e-06" />
            <origin xyz="0.172227 -0.0306439 0.190577" rpy="0 -0 0" />
            <inertia ixx="8.20348e-10" ixy="2.31178e-12" ixz="1.54025e-12" iyy="5.89535e-10" iyz="-2.75788e-10" izz="8.30458e-10" />
        </inertial>
        <visual>
            <origin xyz="0 0 0" rpy="0 -0 0" />
            <geometry>
                <mesh filename="../meshes/gripperfinger_by_ftobler_1.stl" scale="1 1 1" />
            </geometry>
            <material name="0.298039_0.298039_0.298039_0.000000_0.000000">
                <texture />
                <color rgba="0.298039 0.298039 0.298039 1" />
            </material>
        </visual>
    <collision><origin xyz="0 0 0" rpy="0 -0 0" /><geometry>
                <mesh filename="../meshes/gripperfinger_by_ftobler_1.stl" scale="1 1 1" />
            </geometry></collision></link>
    <link name="hex_nut_style_1_am_b18_2_4_1m___hex_nut__style_1___m2_5_x_0_45___d_n_1">
        <inertial>
            <mass value="3.61428e-08" />
            <origin xyz="1.14751e-19 -1.17791e-18 -0.00099897" rpy="0 -0 0" />
            <inertia ixx="8.40217e-14" ixy="0" ixz="0" iyy="8.40217e-14" iyz="0" izz="1.44574e-13" />
        </inertial>
        <visual>
            <origin xyz="0 0 0" rpy="0 -0 0" />
            <geometry>
                <mesh filename="../meshes/hex_nut_style_1_am_b18_2_4_1m___hex_nut__style_1___m2_5_x_0_45___d_n_5.stl" scale="1 1 1" />
            </geometry>
            <material name="0.776471_0.756863_0.737255_0.000000_0.000000">
                <texture />
                <color rgba="0.776471 0.756863 0.737255 1" />
            </material>
        </visual>
    <collision><origin xyz="0 0 0" rpy="0 -0 0" /><geometry>
                <mesh filename="../meshes/hex_nut_style_1_am_b18_2_4_1m___hex_nut__style_1___m2_5_x_0_45___d_n_5.stl" scale="1 1 1" />
            </geometry></collision></link>
    <link name="hex_nut_style_1_am_b18_2_4_1m___hex_nut__style_1___m2_5_x_0_45___d_n_2">
        <inertial>
            <mass value="3.61428e-08" />
            <origin xyz="1.14751e-19 -1.17791e-18 -0.00099897" rpy="0 -0 0" />
            <inertia ixx="8.40217e-14" ixy="0" ixz="0" iyy="8.40217e-14" iyz="0" izz="1.44574e-13" />
        </inertial>
        <visual>
            <origin xyz="0 0 0" rpy="0 -0 0" />
            <geometry>
                <mesh filename="../meshes/hex_nut_style_1_am_b18_2_4_1m___hex_nut__style_1___m2_5_x_0_45___d_n_5.stl" scale="1 1 1" />
            </geometry>
            <material name="0.776471_0.756863_0.737255_0.000000_0.000000">
                <texture />
                <color rgba="0.776471 0.756863 0.737255 1" />
            </material>
        </visual>
    <collision><origin xyz="0 0 0" rpy="0 -0 0" /><geometry>
                <mesh filename="../meshes/hex_nut_style_1_am_b18_2_4_1m___hex_nut__style_1___m2_5_x_0_45___d_n_5.stl" scale="1 1 1" />
            </geometry></collision></link>
    <link name="hex_nut_style_1_am_b18_2_4_1m___hex_nut__style_1___m2_5_x_0_45___d_n_3">
        <inertial>
            <mass value="3.61428e-08" />
            <origin xyz="1.14751e-19 -1.17791e-18 0.00100103" rpy="0 -0 0" />
            <inertia ixx="8.40217e-14" ixy="0" ixz="0" iyy="8.40217e-14" iyz="0" izz="1.44574e-13" />
        </inertial>
        <visual>
            <origin xyz="0 0 0.002" rpy="0 -0 0" />
            <geometry>
                <mesh filename="../meshes/hex_nut_style_1_am_b18_2_4_1m___hex_nut__style_1___m2_5_x_0_45___d_n_5.stl" scale="1 1 1" />
            </geometry>
            <material name="0.776471_0.756863_0.737255_0.000000_0.000000">
                <texture />
                <color rgba="0.776471 0.756863 0.737255 1" />
            </material>
        </visual>
    <collision><origin xyz="0 0 0.002" rpy="0 -0 0" /><geometry>
                <mesh filename="../meshes/hex_nut_style_1_am_b18_2_4_1m___hex_nut__style_1___m2_5_x_0_45___d_n_5.stl" scale="1 1 1" />
            </geometry></collision></link>
    <link name="hex_nut_style_1_am_b18_2_4_1m___hex_nut__style_1___m2_5_x_0_45___d_n_5">
        <inertial>
            <mass value="3.61428e-08" />
            <origin xyz="1.14751e-19 -1.17791e-18 -0.00099897" rpy="0 -0 0" />
            <inertia ixx="8.40217e-14" ixy="0" ixz="0" iyy="8.40217e-14" iyz="0" izz="1.44574e-13" />
        </inertial>
        <visual>
            <origin xyz="0 0 0" rpy="0 -0 0" />
            <geometry>
                <mesh filename="../meshes/hex_nut_style_1_am_b18_2_4_1m___hex_nut__style_1___m2_5_x_0_45___d_n_5.stl" scale="1 1 1" />
            </geometry>
            <material name="0.776471_0.756863_0.737255_0.000000_0.000000">
                <texture />
                <color rgba="0.776471 0.756863 0.737255 1" />
            </material>
        </visual>
    <collision><origin xyz="0 0 0" rpy="0 -0 0" /><geometry>
                <mesh filename="../meshes/hex_nut_style_1_am_b18_2_4_1m___hex_nut__style_1___m2_5_x_0_45___d_n_5.stl" scale="1 1 1" />
            </geometry></collision></link>
    <link name="limit_switch">
        <inertial>
            <mass value="4.37372e-07" />
            <origin xyz="0.002305 0.00290174 -0.00315396" rpy="0 -0 0" />
            <inertia ixx="7.46487e-12" ixy="0" ixz="-3.07011e-13" iyy="8.10428e-12" iyz="0" izz="2.95151e-12" />
        </inertial>
        <visual>
            <origin xyz="-0.0640691 0.0786651 0.00585" rpy="0 -0 0" />
            <geometry>
                <mesh filename="../meshes/limit_switch_2.stl" scale="1 1 1" />
            </geometry>
            <material name="0.019608_0.019608_0.019608_0.000000_0.000000">
                <texture />
                <color rgba="0.0196078 0.0196078 0.0196078 1" />
            </material>
        </visual>
    <collision><origin xyz="-0.0640691 0.0786651 0.00585" rpy="0 -0 0" /><geometry>
                <mesh filename="../meshes/limit_switch_2.stl" scale="1 1 1" />
            </geometry></collision></link>
    <link name="limit_switch_1">
        <inertial>
            <mass value="4.37372e-07" />
            <origin xyz="0.002305 0.00290174 -0.00315396" rpy="0 -0 0" />
            <inertia ixx="7.46487e-12" ixy="0" ixz="-3.07011e-13" iyy="8.10428e-12" iyz="0" izz="2.95151e-12" />
        </inertial>
        <visual>
            <origin xyz="-0.0640691 0.0786651 0.00585" rpy="0 -0 0" />
            <geometry>
                <mesh filename="../meshes/limit_switch_2.stl" scale="1 1 1" />
            </geometry>
            <material name="0.019608_0.019608_0.019608_0.000000_0.000000">
                <texture />
                <color rgba="0.0196078 0.0196078 0.0196078 1" />
            </material>
        </visual>
    <collision><origin xyz="-0.0640691 0.0786651 0.00585" rpy="0 -0 0" /><geometry>
                <mesh filename="../meshes/limit_switch_2.stl" scale="1 1 1" />
            </geometry></collision></link>
    <link name="limit_switch_2">
        <inertial>
            <mass value="4.37372e-07" />
            <origin xyz="0.002305 0.00290174 -0.00315396" rpy="0 -0 0" />
            <inertia ixx="7.46487e-12" ixy="0" ixz="-3.07011e-13" iyy="8.10428e-12" iyz="0" izz="2.95151e-12" />
        </inertial>
        <visual>
            <origin xyz="-0.0640691 0.0786651 0.00585" rpy="0 -0 0" />
            <geometry>
                <mesh filename="../meshes/limit_switch_2.stl" scale="1 1 1" />
            </geometry>
            <material name="0.019608_0.019608_0.019608_0.000000_0.000000">
                <texture />
                <color rgba="0.0196078 0.0196078 0.0196078 1" />
            </material>
        </visual>
    <collision><origin xyz="-0.0640691 0.0786651 0.00585" rpy="0 -0 0" /><geometry>
                <mesh filename="../meshes/limit_switch_2.stl" scale="1 1 1" />
            </geometry></collision></link>
    <link name="lower_shank_140">
        <inertial>
            <mass value="4.07717e-05" />
            <origin xyz="-0.0614049 0.0102085 -0.00216941" rpy="0 -0 0" />
            <inertia ixx="4.27132e-09" ixy="1.75967e-09" ixz="-3.25931e-09" iyy="9.56728e-08" iyz="6.22103e-11" izz="9.64503e-08" />
        </inertial>
        <visual>
            <origin xyz="-0.117686 0.659005 -0.110224" rpy="0 -0 0" />
            <geometry>
                <mesh filename="../meshes/lower_shank_140.stl" scale="1 1 1" />
            </geometry>
            <material name="0.909804_0.443137_0.031373_0.000000_0.000000">
                <texture />
                <color rgba="0.909804 0.443137 0.0313726 1" />
            </material>
        </visual>
    <collision><origin xyz="-0.117686 0.659005 -0.110224" rpy="0 -0 0" /><geometry>
                <mesh filename="../meshes/lower_shank_140.stl" scale="1 1 1" />
            </geometry></collision></link>
    <link name="manipulator_dual">
        <inertial>
            <mass value="1.86105e-05" />
            <origin xyz="-0.00356158 0.0220001 -0.0159419" rpy="0 -0 0" />
            <inertia ixx="5.21773e-09" ixy="3.20908e-15" ixz="3.12277e-10" iyy="3.64946e-09" iyz="-4.73798e-15" izz="6.02391e-09" />
        </inertial>
        <visual>
            <origin xyz="-0.197858 0.538505 -0.218759" rpy="0 -0 0" />
            <geometry>
                <mesh filename="../meshes/manipulator_dual.stl" scale="1 1 1" />
            </geometry>
            <material name="0.298039_0.298039_0.298039_0.000000_0.000000">
                <texture />
                <color rgba="0.298039 0.298039 0.298039 1" />
            </material>
        </visual>
    <collision><origin xyz="-0.197858 0.538505 -0.218759" rpy="0 -0 0" /><geometry>
                <mesh filename="../meshes/manipulator_dual.stl" scale="1 1 1" />
            </geometry></collision></link>
    <link name="parallel_4_0" />
    <link name="parallel_4_1" />
    <link name="parallel_4_2" />
    <link name="pleuel_140">
        <inertial>
            <mass value="8.66732e-06" />
            <origin xyz="-0.0570102 0.0406136 0.00275546" rpy="0 -0 0" />
            <inertia ixx="6.81312e-09" ixy="9.33524e-09" ixz="4.14189e-11" iyy="1.32694e-08" iyz="-2.95172e-11" izz="2.00339e-08" />
        </inertial>
        <visual>
            <origin xyz="-0.0246033 0.560849 0" rpy="0 -0 0" />
            <geometry>
                <mesh filename="../meshes/pleuel_140.stl" scale="1 1 1" />
            </geometry>
            <material name="0.298039_0.298039_0.298039_0.000000_0.000000">
                <texture />
                <color rgba="0.298039 0.298039 0.298039 1" />
            </material>
        </visual>
    <collision><origin xyz="-0.0246033 0.560849 0" rpy="0 -0 0" /><geometry>
                <mesh filename="../meshes/pleuel_140.stl" scale="1 1 1" />
            </geometry></collision></link>
    <link name="pleuel_bend_140">
        <inertial>
            <mass value="8.88371e-06" />
            <origin xyz="-0.0552254 -0.00267208 0.044707" rpy="0 -0 0" />
            <inertia ixx="9.12195e-09" ixy="8.52545e-13" ixz="1.00708e-08" iyy="2.08688e-08" iyz="6.40815e-13" izz="1.17958e-08" />
        </inertial>
        <visual>
            <origin xyz="-0.12948 0.541505 -0.0540177" rpy="0 -0 0" />
            <geometry>
                <mesh filename="../meshes/pleuel_bend_140_1.stl" scale="1 1 1" />
            </geometry>
            <material name="0.909804_0.443137_0.031373_0.000000_0.000000">
                <texture />
                <color rgba="0.909804 0.443137 0.0313726 1" />
            </material>
        </visual>
    <collision><origin xyz="-0.12948 0.541505 -0.0540177" rpy="0 -0 0" /><geometry>
                <mesh filename="../meshes/pleuel_bend_140_1.stl" scale="1 1 1" />
            </geometry></collision></link>
    <link name="pleuel_bend_140_1">
        <inertial>
            <mass value="8.88371e-06" />
            <origin xyz="0.0471859 -0.00267208 -0.0507506" rpy="0 -0 0" />
            <inertia ixx="9.12195e-09" ixy="8.52545e-13" ixz="1.00708e-08" iyy="2.08688e-08" iyz="6.40815e-13" izz="1.17958e-08" />
        </inertial>
        <visual>
            <origin xyz="-0.0270684 0.541505 -0.149475" rpy="0 -0 0" />
            <geometry>
                <mesh filename="../meshes/pleuel_bend_140_1.stl" scale="1 1 1" />
            </geometry>
            <material name="0.909804_0.443137_0.031373_0.000000_0.000000">
                <texture />
                <color rgba="0.909804 0.443137 0.0313726 1" />
            </material>
        </visual>
    <collision><origin xyz="-0.0270684 0.541505 -0.149475" rpy="0 -0 0" /><geometry>
                <mesh filename="../meshes/pleuel_bend_140_1.stl" scale="1 1 1" />
            </geometry></collision></link>
    <link name="pleuel_bend_140_mirrored">
        <inertial>
            <mass value="8.88371e-06" />
            <origin xyz="-0.0552254 0.00267208 0.044707" rpy="0 -0 0" />
            <inertia ixx="9.12195e-09" ixy="-8.5254e-13" ixz="1.00708e-08" iyy="2.08688e-08" iyz="-6.40819e-13" izz="1.17958e-08" />
        </inertial>
        <visual>
            <origin xyz="-0.12948 0.541505 -0.0540177" rpy="0 -0 0" />
            <geometry>
                <mesh filename="../meshes/pleuel_bend_140_mirrored_1.stl" scale="1 1 1" />
            </geometry>
            <material name="0.909804_0.443137_0.031373_0.000000_0.000000">
                <texture />
                <color rgba="0.909804 0.443137 0.0313726 1" />
            </material>
        </visual>
    <collision><origin xyz="-0.12948 0.541505 -0.0540177" rpy="0 -0 0" /><geometry>
                <mesh filename="../meshes/pleuel_bend_140_mirrored_1.stl" scale="1 1 1" />
            </geometry></collision></link>
    <link name="pleuel_bend_140_mirrored_1">
        <inertial>
            <mass value="8.88371e-06" />
            <origin xyz="0.0471859 0.00267208 -0.0507506" rpy="0 -0 0" />
            <inertia ixx="9.12195e-09" ixy="-8.5254e-13" ixz="1.00708e-08" iyy="2.08688e-08" iyz="-6.40819e-13" izz="1.17958e-08" />
        </inertial>
        <visual>
            <origin xyz="-0.0270684 0.541505 -0.149475" rpy="0 -0 0" />
            <geometry>
                <mesh filename="../meshes/pleuel_bend_140_mirrored_1.stl" scale="1 1 1" />
            </geometry>
            <material name="0.909804_0.443137_0.031373_0.000000_0.000000">
                <texture />
                <color rgba="0.909804 0.443137 0.0313726 1" />
            </material>
        </visual>
    <collision><origin xyz="-0.0270684 0.541505 -0.149475" rpy="0 -0 0" /><geometry>
                <mesh filename="../meshes/pleuel_bend_140_mirrored_1.stl" scale="1 1 1" />
            </geometry></collision></link>
    <link name="prevailing_torque_hex_flange_nut_am_am_m6_n_1">
        <inertial>
            <mass value="5.54873e-07" />
            <origin xyz="3.0972e-10 9.30012e-11 0.0030648" rpy="0 -0 0" />
            <inertia ixx="8.09561e-12" ixy="0" ixz="0" iyy="8.0956e-12" iyz="0" izz="1.11189e-11" />
        </inertial>
        <visual>
            <origin xyz="0 0 0.0073" rpy="0 -0 0" />
            <geometry>
                <mesh filename="../meshes/prevailing_torque_hex_flange_nut_am_am_m6_n_1.stl" scale="1 1 1" />
            </geometry>
            <material name="0.776471_0.756863_0.737255_0.000000_0.000000">
                <texture />
                <color rgba="0.776471 0.756863 0.737255 1" />
            </material>
        </visual>
    <collision><origin xyz="0 0 0.0073" rpy="0 -0 0" /><geometry>
                <mesh filename="../meshes/prevailing_torque_hex_flange_nut_am_am_m6_n_1.stl" scale="1 1 1" />
            </geometry></collision></link>
    <link name="robot_belt_arm_basering">
        <inertial>
            <mass value="1.01419e-05" />
            <origin xyz="0.103846 -0.0490051 -0.0655056" rpy="0 -0 0" />
            <inertia ixx="1.2594e-08" ixy="0" ixz="-6.1665e-11" iyy="1.05985e-08" iyz="0" izz="2.31591e-08" />
        </inertial>
        <visual>
            <origin xyz="0 0 0" rpy="0 -0 0" />
            <geometry>
                <mesh filename="../meshes/robot_belt_arm_basering.stl" scale="1 1 1" />
            </geometry>
            <material name="0.909804_0.443137_0.031373_0.000000_0.000000">
                <texture />
                <color rgba="0.909804 0.443137 0.0313726 1" />
            </material>
        </visual>
    <collision><origin xyz="0 0 0" rpy="0 -0 0" /><geometry>
                <mesh filename="../meshes/robot_belt_arm_basering.stl" scale="1 1 1" />
            </geometry></collision></link>
    <link name="robot_belt_arm_endstop___mymod">
        <inertial>
            <mass value="4.31512e-06" />
            <origin xyz="-0.00486144 -0.0279785 0.00347698" rpy="0 -0 0" />
            <inertia ixx="1.20814e-09" ixy="-3.2158e-11" ixz="9.90297e-11" iyy="6.39665e-10" iyz="1.39582e-10" izz="6.92063e-10" />
        </inertial>
        <visual>
            <origin xyz="-0.0774887 0.0260051 -0.037" rpy="0 -0 0" />
            <geometry>
                <mesh filename="../meshes/robot_belt_arm_endstop___mymod.stl" scale="1 1 1" />
            </geometry>
            <material name="0.298039_0.298039_0.298039_0.000000_0.000000">
                <texture />
                <color rgba="0.298039 0.298039 0.298039 1" />
            </material>
        </visual>
    <collision><origin xyz="-0.0774887 0.0260051 -0.037" rpy="0 -0 0" /><geometry>
                <mesh filename="../meshes/robot_belt_arm_endstop___mymod.stl" scale="1 1 1" />
            </geometry></collision></link>
    <link name="robot_belt_arm_gear_body">
        <inertial>
            <mass value="1.12002e-05" />
            <origin xyz="9.98615e-10 -0.00319577 2.52749e-09" rpy="0 -0 0" />
            <inertia ixx="2.60723e-09" ixy="0" ixz="0" iyy="5.13533e-09" iyz="0" izz="2.60723e-09" />
        </inertial>
        <visual>
            <origin xyz="-0.0999999 0.0625 -0.0625" rpy="0 -0 0" />
            <geometry>
                <mesh filename="../meshes/robot_belt_arm_gear_body_1.stl" scale="1 1 1" />
            </geometry>
            <material name="0.298039_0.298039_0.298039_0.000000_0.000000">
                <texture />
                <color rgba="0.298039 0.298039 0.298039 1" />
            </material>
        </visual>
    <collision><origin xyz="-0.0999999 0.0625 -0.0625" rpy="0 -0 0" /><geometry>
                <mesh filename="../meshes/robot_belt_arm_gear_body_1.stl" scale="1 1 1" />
            </geometry></collision></link>
    <link name="robot_belt_arm_gear_body_1">
        <inertial>
            <mass value="1.12002e-05" />
            <origin xyz="9.98615e-10 0.00330423 2.52749e-09" rpy="0 -0 0" />
            <inertia ixx="2.60723e-09" ixy="0" ixz="0" iyy="5.13533e-09" iyz="0" izz="2.60723e-09" />
        </inertial>
        <visual>
            <origin xyz="-0.0999999 0.069 -0.0625" rpy="0 -0 0" />
            <geometry>
                <mesh filename="../meshes/robot_belt_arm_gear_body_1.stl" scale="1 1 1" />
            </geometry>
            <material name="0.298039_0.298039_0.298039_0.000000_0.000000">
                <texture />
                <color rgba="0.298039 0.298039 0.298039 1" />
            </material>
        </visual>
    <collision><origin xyz="-0.0999999 0.069 -0.0625" rpy="0 -0 0" /><geometry>
                <mesh filename="../meshes/robot_belt_arm_gear_body_1.stl" scale="1 1 1" />
            </geometry></collision></link>
    <link name="robot_belt_arm_leg">
        <inertial>
            <mass value="1.42189e-05" />
            <origin xyz="8.15356e-12 0.0152179 0.0190616" rpy="0 -0 0" />
            <inertia ixx="2.39223e-09" ixy="0" ixz="0" iyy="3.2551e-09" iyz="-9.64423e-10" izz="2.33108e-09" />
        </inertial>
        <visual>
            <origin xyz="-0.0999887 0.101005 0.0632" rpy="0 -0 0" />
            <geometry>
                <mesh filename="../meshes/robot_belt_arm_leg_2.stl" scale="1 1 1" />
            </geometry>
            <material name="0.298039_0.298039_0.298039_0.000000_0.000000">
                <texture />
                <color rgba="0.298039 0.298039 0.298039 1" />
            </material>
        </visual>
    <collision><origin xyz="-0.0999887 0.101005 0.0632" rpy="0 -0 0" /><geometry>
                <mesh filename="../meshes/robot_belt_arm_leg_2.stl" scale="1 1 1" />
            </geometry></collision></link>
    <link name="robot_belt_arm_leg_1">
        <inertial>
            <mass value="1.42189e-05" />
            <origin xyz="8.15356e-12 0.0152179 0.0190616" rpy="0 -0 0" />
            <inertia ixx="2.39223e-09" ixy="0" ixz="0" iyy="3.2551e-09" iyz="-9.64423e-10" izz="2.33108e-09" />
        </inertial>
        <visual>
            <origin xyz="-0.0999887 0.101005 0.0632" rpy="0 -0 0" />
            <geometry>
                <mesh filename="../meshes/robot_belt_arm_leg_2.stl" scale="1 1 1" />
            </geometry>
            <material name="0.298039_0.298039_0.298039_0.000000_0.000000">
                <texture />
                <color rgba="0.298039 0.298039 0.298039 1" />
            </material>
        </visual>
    <collision><origin xyz="-0.0999887 0.101005 0.0632" rpy="0 -0 0" /><geometry>
                <mesh filename="../meshes/robot_belt_arm_leg_2.stl" scale="1 1 1" />
            </geometry></collision></link>
    <link name="robot_belt_arm_leg_2">
        <inertial>
            <mass value="1.42189e-05" />
            <origin xyz="8.15356e-12 0.0152179 0.0190616" rpy="0 -0 0" />
            <inertia ixx="2.39223e-09" ixy="0" ixz="0" iyy="3.2551e-09" iyz="-9.64423e-10" izz="2.33108e-09" />
        </inertial>
        <visual>
            <origin xyz="-0.0999887 0.101005 0.0632" rpy="0 -0 0" />
            <geometry>
                <mesh filename="../meshes/robot_belt_arm_leg_2.stl" scale="1 1 1" />
            </geometry>
            <material name="0.298039_0.298039_0.298039_0.000000_0.000000">
                <texture />
                <color rgba="0.298039 0.298039 0.298039 1" />
            </material>
        </visual>
    <collision><origin xyz="-0.0999887 0.101005 0.0632" rpy="0 -0 0" /><geometry>
                <mesh filename="../meshes/robot_belt_arm_leg_2.stl" scale="1 1 1" />
            </geometry></collision></link>
    <link name="robot_belt_arm_lever___mymod">
        <inertial>
            <mass value="1.00295e-05" />
            <origin xyz="-0.0129468 -0.00400119 -0.00683616" rpy="0 -0 0" />
            <inertia ixx="1.09738e-09" ixy="1.55157e-13" ixz="-8.41221e-10" iyy="3.28828e-09" iyz="8.19259e-14" izz="2.29642e-09" />
        </inertial>
        <visual>
            <origin xyz="-0.1 0.0355 -0.0625" rpy="0 -0 0" />
            <geometry>
                <mesh filename="../meshes/robot_belt_arm_lever___mymod.stl" scale="1 1 1" />
            </geometry>
            <material name="0.909804_0.443137_0.031373_0.000000_0.000000">
                <texture />
                <color rgba="0.909804 0.443137 0.0313726 1" />
            </material>
        </visual>
    <collision><origin xyz="-0.1 0.0355 -0.0625" rpy="0 -0 0" /><geometry>
                <mesh filename="../meshes/robot_belt_arm_lever___mymod.stl" scale="1 1 1" />
            </geometry></collision></link>
    <link name="robot_belt_arm_main_body_v2______mymod">
        <inertial>
            <mass value="4.47417e-05" />
            <origin xyz="-0.00169715 -8.18852e-08 0.0312764" rpy="0 -0 0" />
            <inertia ixx="5.09789e-08" ixy="1.11364e-13" ixz="5.69671e-09" iyy="4.24137e-08" iyz="-9.27109e-14" izz="3.03074e-08" />
        </inertial>
        <visual>
            <origin xyz="-0.0999887 0.0490051 0.0015" rpy="0 -0 0" />
            <geometry>
                <mesh filename="../meshes/robot_belt_arm_main_body_v2______mymod.stl" scale="1 1 1" />
            </geometry>
            <material name="0.909804_0.443137_0.031373_0.000000_0.000000">
                <texture />
                <color rgba="0.909804 0.443137 0.0313726 1" />
            </material>
        </visual>
    <collision><origin xyz="-0.0999887 0.0490051 0.0015" rpy="0 -0 0" /><geometry>
                <mesh filename="../meshes/robot_belt_arm_main_body_v2______mymod.stl" scale="1 1 1" />
            </geometry></collision></link>
    <link name="robot_belt_arm_rotategear___mymod">
        <inertial>
            <mass value="1.60564e-05" />
            <origin xyz="-1.55585e-05 1.59387e-05 -0.00412005" rpy="0 -0 0" />
            <inertia ixx="3.9102e-09" ixy="3.71464e-14" ixz="-4.55715e-13" iyy="3.90519e-09" iyz="2.24593e-13" izz="7.57541e-09" />
        </inertial>
        <visual>
            <origin xyz="-0.0999887 0.0490051 0.0015" rpy="0 -0 0" />
            <geometry>
                <mesh filename="../meshes/robot_belt_arm_rotategear___mymod.stl" scale="1 1 1" />
            </geometry>
            <material name="0.298039_0.298039_0.298039_0.000000_0.000000">
                <texture />
                <color rgba="0.298039 0.298039 0.298039 1" />
            </material>
        </visual>
    <collision><origin xyz="-0.0999887 0.0490051 0.0015" rpy="0 -0 0" /><geometry>
                <mesh filename="../meshes/robot_belt_arm_rotategear___mymod.stl" scale="1 1 1" />
            </geometry></collision></link>
    <link name="robot_belt_arm_socket_v2">
        <inertial>
            <mass value="4.17145e-05" />
            <origin xyz="-0.00419504 -0.0353654 0.00537763" rpy="0 -0 0" />
            <inertia ixx="1.46523e-08" ixy="-2.12323e-09" ixz="-3.80484e-10" iyy="2.12835e-08" iyz="2.53443e-10" izz="3.46136e-08" />
        </inertial>
        <visual>
            <origin xyz="-0.0999887 0.0153449 0.0272" rpy="0 -0 0" />
            <geometry>
                <mesh filename="../meshes/robot_belt_arm_socket_v2.stl" scale="1 1 1" />
            </geometry>
            <material name="0.909804_0.443137_0.031373_0.000000_0.000000">
                <texture />
                <color rgba="0.909804 0.443137 0.0313726 1" />
            </material>
        </visual>
    <collision><origin xyz="-0.0999887 0.0153449 0.0272" rpy="0 -0 0" /><geometry>
                <mesh filename="../meshes/robot_belt_arm_socket_v2.stl" scale="1 1 1" />
            </geometry></collision></link>
    <link name="robot_belt_arm_stabilizer___logigate">
        <inertial>
            <mass value="2.08009e-06" />
            <origin xyz="0.00169962 0.0230197 0.00496639" rpy="0 -0 0" />
            <inertia ixx="5.55096e-10" ixy="-8.40035e-14" ixz="1.43362e-13" iyy="3.43136e-11" iyz="-1.86001e-13" izz="5.25398e-10" />
        </inertial>
        <visual>
            <origin xyz="-0.120989 0.0720051 -0.023" rpy="0 -0 0" />
            <geometry>
                <mesh filename="../meshes/robot_belt_arm_stabilizer___logigate.stl" scale="1 1 1" />
            </geometry>
            <material name="0.298039_0.298039_0.298039_0.000000_0.000000">
                <texture />
                <color rgba="0.298039 0.298039 0.298039 1" />
            </material>
        </visual>
    <collision><origin xyz="-0.120989 0.0720051 -0.023" rpy="0 -0 0" /><geometry>
                <mesh filename="../meshes/robot_belt_arm_stabilizer___logigate.stl" scale="1 1 1" />
            </geometry></collision></link>
    <link name="robot_belt_arm_triplate">
        <inertial>
            <mass value="7.1204e-06" />
            <origin xyz="0.022488 0.0062017 0.000309294" rpy="0 -0 0" />
            <inertia ixx="5.28717e-10" ixy="-6.15682e-11" ixz="1.71862e-11" iyy="1.966e-09" iyz="4.74273e-12" izz="1.50043e-09" />
        </inertial>
        <visual>
            <origin xyz="0.0183148 0.075 -0.155744" rpy="0 -0 0" />
            <geometry>
                <mesh filename="../meshes/robot_belt_arm_triplate.stl" scale="1 1 1" />
            </geometry>
            <material name="0.298039_0.298039_0.298039_0.000000_0.000000">
                <texture />
                <color rgba="0.298039 0.298039 0.298039 1" />
            </material>
        </visual>
    <collision><origin xyz="0.0183148 0.075 -0.155744" rpy="0 -0 0" /><geometry>
                <mesh filename="../meshes/robot_belt_arm_triplate.stl" scale="1 1 1" />
            </geometry></collision></link>
    <link name="root">
        </link>
    <link name="socket_button_head_cap_screw_am_b18_3_4m___3_x_0_5_x_6_sbhcs___n">
        <inertial>
            <mass value="6.89009e-08" />
            <origin xyz="0.00157643 -7.69915e-13 -2.14314e-12" rpy="0 -0 0" />
            <inertia ixx="1.47463e-13" ixy="0" ixz="0" iyy="4.1428e-13" iyz="0" izz="4.14278e-13" />
        </inertial>
        <visual>
            <origin xyz="-0.00165 0 0" rpy="0 -0 0" />
            <geometry>
                <mesh filename="../meshes/socket_button_head_cap_screw_am_b18_3_4m___3_x_0_5_x_6_sbhcs___n_1.stl" scale="1 1 1" />
            </geometry>
            <material name="0.776471_0.756863_0.737255_0.000000_0.000000">
                <texture />
                <color rgba="0.776471 0.756863 0.737255 1" />
            </material>
        </visual>
    <collision><origin xyz="-0.00165 0 0" rpy="0 -0 0" /><geometry>
                <mesh filename="../meshes/socket_button_head_cap_screw_am_b18_3_4m___3_x_0_5_x_6_sbhcs___n_1.stl" scale="1 1 1" />
            </geometry></collision></link>
    <link name="socket_button_head_cap_screw_am_b18_3_4m___3_x_0_5_x_6_sbhcs___n_1">
        <inertial>
            <mass value="6.89009e-08" />
            <origin xyz="0.00157643 -7.69915e-13 -2.14314e-12" rpy="0 -0 0" />
            <inertia ixx="1.47463e-13" ixy="0" ixz="0" iyy="4.1428e-13" iyz="0" izz="4.14278e-13" />
        </inertial>
        <visual>
            <origin xyz="-0.00165 0 0" rpy="0 -0 0" />
            <geometry>
                <mesh filename="../meshes/socket_button_head_cap_screw_am_b18_3_4m___3_x_0_5_x_6_sbhcs___n_1.stl" scale="1 1 1" />
            </geometry>
            <material name="0.776471_0.756863_0.737255_0.000000_0.000000">
                <texture />
                <color rgba="0.776471 0.756863 0.737255 1" />
            </material>
        </visual>
    <collision><origin xyz="-0.00165 0 0" rpy="0 -0 0" /><geometry>
                <mesh filename="../meshes/socket_button_head_cap_screw_am_b18_3_4m___3_x_0_5_x_6_sbhcs___n_1.stl" scale="1 1 1" />
            </geometry></collision></link>
    <link name="socket_button_head_cap_screw_am_b18_3_4m___3_x_0_5_x_8_sbhcs___n">
        <inertial>
            <mass value="8.30381e-08" />
            <origin xyz="0.00249142 -7.46853e-13 -2.0375e-12" rpy="0 -0 0" />
            <inertia ixx="1.63366e-13" ixy="0" ixz="0" iyy="7.65861e-13" iyz="0" izz="7.65858e-13" />
        </inertial>
        <visual>
            <origin xyz="-0.00165 0 0" rpy="0 -0 0" />
            <geometry>
                <mesh filename="../meshes/socket_button_head_cap_screw_am_b18_3_4m___3_x_0_5_x_8_sbhcs___n_9.stl" scale="1 1 1" />
            </geometry>
            <material name="0.776471_0.756863_0.737255_0.000000_0.000000">
                <texture />
                <color rgba="0.776471 0.756863 0.737255 1" />
            </material>
        </visual>
    <collision><origin xyz="-0.00165 0 0" rpy="0 -0 0" /><geometry>
                <mesh filename="../meshes/socket_button_head_cap_screw_am_b18_3_4m___3_x_0_5_x_8_sbhcs___n_9.stl" scale="1 1 1" />
            </geometry></collision></link>
    <link name="socket_button_head_cap_screw_am_b18_3_4m___3_x_0_5_x_8_sbhcs___n_1">
        <inertial>
            <mass value="8.30381e-08" />
            <origin xyz="0.00249142 -7.46853e-13 -2.0375e-12" rpy="0 -0 0" />
            <inertia ixx="1.63366e-13" ixy="0" ixz="0" iyy="7.65861e-13" iyz="0" izz="7.65858e-13" />
        </inertial>
        <visual>
            <origin xyz="-0.00165 0 0" rpy="0 -0 0" />
            <geometry>
                <mesh filename="../meshes/socket_button_head_cap_screw_am_b18_3_4m___3_x_0_5_x_8_sbhcs___n_9.stl" scale="1 1 1" />
            </geometry>
            <material name="0.776471_0.756863_0.737255_0.000000_0.000000">
                <texture />
                <color rgba="0.776471 0.756863 0.737255 1" />
            </material>
        </visual>
    <collision><origin xyz="-0.00165 0 0" rpy="0 -0 0" /><geometry>
                <mesh filename="../meshes/socket_button_head_cap_screw_am_b18_3_4m___3_x_0_5_x_8_sbhcs___n_9.stl" scale="1 1 1" />
            </geometry></collision></link>
    <link name="socket_button_head_cap_screw_am_b18_3_4m___3_x_0_5_x_8_sbhcs___n_10">
        <inertial>
            <mass value="8.30381e-08" />
            <origin xyz="0.00249142 -7.46853e-13 -2.0375e-12" rpy="0 -0 0" />
            <inertia ixx="1.63366e-13" ixy="0" ixz="0" iyy="7.65861e-13" iyz="0" izz="7.65858e-13" />
        </inertial>
        <visual>
            <origin xyz="-0.00165 0 0" rpy="0 -0 0" />
            <geometry>
                <mesh filename="../meshes/socket_button_head_cap_screw_am_b18_3_4m___3_x_0_5_x_8_sbhcs___n_9.stl" scale="1 1 1" />
            </geometry>
            <material name="0.776471_0.756863_0.737255_0.000000_0.000000">
                <texture />
                <color rgba="0.776471 0.756863 0.737255 1" />
            </material>
        </visual>
    <collision><origin xyz="-0.00165 0 0" rpy="0 -0 0" /><geometry>
                <mesh filename="../meshes/socket_button_head_cap_screw_am_b18_3_4m___3_x_0_5_x_8_sbhcs___n_9.stl" scale="1 1 1" />
            </geometry></collision></link>
    <link name="socket_button_head_cap_screw_am_b18_3_4m___3_x_0_5_x_8_sbhcs___n_11">
        <inertial>
            <mass value="8.30381e-08" />
            <origin xyz="0.00249142 -7.46853e-13 -2.0375e-12" rpy="0 -0 0" />
            <inertia ixx="1.63366e-13" ixy="0" ixz="0" iyy="7.65861e-13" iyz="0" izz="7.65858e-13" />
        </inertial>
        <visual>
            <origin xyz="-0.00165 0 0" rpy="0 -0 0" />
            <geometry>
                <mesh filename="../meshes/socket_button_head_cap_screw_am_b18_3_4m___3_x_0_5_x_8_sbhcs___n_9.stl" scale="1 1 1" />
            </geometry>
            <material name="0.776471_0.756863_0.737255_0.000000_0.000000">
                <texture />
                <color rgba="0.776471 0.756863 0.737255 1" />
            </material>
        </visual>
    <collision><origin xyz="-0.00165 0 0" rpy="0 -0 0" /><geometry>
                <mesh filename="../meshes/socket_button_head_cap_screw_am_b18_3_4m___3_x_0_5_x_8_sbhcs___n_9.stl" scale="1 1 1" />
            </geometry></collision></link>
    <link name="socket_button_head_cap_screw_am_b18_3_4m___3_x_0_5_x_8_sbhcs___n_12">
        <inertial>
            <mass value="8.30381e-08" />
            <origin xyz="0.00249142 -7.46853e-13 -2.0375e-12" rpy="0 -0 0" />
            <inertia ixx="1.63366e-13" ixy="0" ixz="0" iyy="7.65861e-13" iyz="0" izz="7.65858e-13" />
        </inertial>
        <visual>
            <origin xyz="-0.00165 0 0" rpy="0 -0 0" />
            <geometry>
                <mesh filename="../meshes/socket_button_head_cap_screw_am_b18_3_4m___3_x_0_5_x_8_sbhcs___n_9.stl" scale="1 1 1" />
            </geometry>
            <material name="0.776471_0.756863_0.737255_0.000000_0.000000">
                <texture />
                <color rgba="0.776471 0.756863 0.737255 1" />
            </material>
        </visual>
    <collision><origin xyz="-0.00165 0 0" rpy="0 -0 0" /><geometry>
                <mesh filename="../meshes/socket_button_head_cap_screw_am_b18_3_4m___3_x_0_5_x_8_sbhcs___n_9.stl" scale="1 1 1" />
            </geometry></collision></link>
    <link name="socket_button_head_cap_screw_am_b18_3_4m___3_x_0_5_x_8_sbhcs___n_13">
        <inertial>
            <mass value="8.30381e-08" />
            <origin xyz="0.00249142 -7.46853e-13 -2.0375e-12" rpy="0 -0 0" />
            <inertia ixx="1.63366e-13" ixy="0" ixz="0" iyy="7.65861e-13" iyz="0" izz="7.65858e-13" />
        </inertial>
        <visual>
            <origin xyz="-0.00165 0 0" rpy="0 -0 0" />
            <geometry>
                <mesh filename="../meshes/socket_button_head_cap_screw_am_b18_3_4m___3_x_0_5_x_8_sbhcs___n_9.stl" scale="1 1 1" />
            </geometry>
            <material name="0.776471_0.756863_0.737255_0.000000_0.000000">
                <texture />
                <color rgba="0.776471 0.756863 0.737255 1" />
            </material>
        </visual>
    <collision><origin xyz="-0.00165 0 0" rpy="0 -0 0" /><geometry>
                <mesh filename="../meshes/socket_button_head_cap_screw_am_b18_3_4m___3_x_0_5_x_8_sbhcs___n_9.stl" scale="1 1 1" />
            </geometry></collision></link>
    <link name="socket_button_head_cap_screw_am_b18_3_4m___3_x_0_5_x_8_sbhcs___n_14">
        <inertial>
            <mass value="8.30381e-08" />
            <origin xyz="0.00249142 -7.46853e-13 -2.0375e-12" rpy="0 -0 0" />
            <inertia ixx="1.63366e-13" ixy="0" ixz="0" iyy="7.65861e-13" iyz="0" izz="7.65858e-13" />
        </inertial>
        <visual>
            <origin xyz="-0.00165 0 0" rpy="0 -0 0" />
            <geometry>
                <mesh filename="../meshes/socket_button_head_cap_screw_am_b18_3_4m___3_x_0_5_x_8_sbhcs___n_9.stl" scale="1 1 1" />
            </geometry>
            <material name="0.776471_0.756863_0.737255_0.000000_0.000000">
                <texture />
                <color rgba="0.776471 0.756863 0.737255 1" />
            </material>
        </visual>
    <collision><origin xyz="-0.00165 0 0" rpy="0 -0 0" /><geometry>
                <mesh filename="../meshes/socket_button_head_cap_screw_am_b18_3_4m___3_x_0_5_x_8_sbhcs___n_9.stl" scale="1 1 1" />
            </geometry></collision></link>
    <link name="socket_button_head_cap_screw_am_b18_3_4m___3_x_0_5_x_8_sbhcs___n_15">
        <inertial>
            <mass value="8.30381e-08" />
            <origin xyz="0.00249142 -7.46853e-13 -2.0375e-12" rpy="0 -0 0" />
            <inertia ixx="1.63366e-13" ixy="0" ixz="0" iyy="7.65861e-13" iyz="0" izz="7.65858e-13" />
        </inertial>
        <visual>
            <origin xyz="-0.00165 0 0" rpy="0 -0 0" />
            <geometry>
                <mesh filename="../meshes/socket_button_head_cap_screw_am_b18_3_4m___3_x_0_5_x_8_sbhcs___n_9.stl" scale="1 1 1" />
            </geometry>
            <material name="0.776471_0.756863_0.737255_0.000000_0.000000">
                <texture />
                <color rgba="0.776471 0.756863 0.737255 1" />
            </material>
        </visual>
    <collision><origin xyz="-0.00165 0 0" rpy="0 -0 0" /><geometry>
                <mesh filename="../meshes/socket_button_head_cap_screw_am_b18_3_4m___3_x_0_5_x_8_sbhcs___n_9.stl" scale="1 1 1" />
            </geometry></collision></link>
    <link name="socket_button_head_cap_screw_am_b18_3_4m___3_x_0_5_x_8_sbhcs___n_16">
        <inertial>
            <mass value="8.30381e-08" />
            <origin xyz="0.00249142 -7.46853e-13 -2.0375e-12" rpy="0 -0 0" />
            <inertia ixx="1.63366e-13" ixy="0" ixz="0" iyy="7.65861e-13" iyz="0" izz="7.65858e-13" />
        </inertial>
        <visual>
            <origin xyz="-0.00165 0 0" rpy="0 -0 0" />
            <geometry>
                <mesh filename="../meshes/socket_button_head_cap_screw_am_b18_3_4m___3_x_0_5_x_8_sbhcs___n_9.stl" scale="1 1 1" />
            </geometry>
            <material name="0.776471_0.756863_0.737255_0.000000_0.000000">
                <texture />
                <color rgba="0.776471 0.756863 0.737255 1" />
            </material>
        </visual>
    <collision><origin xyz="-0.00165 0 0" rpy="0 -0 0" /><geometry>
                <mesh filename="../meshes/socket_button_head_cap_screw_am_b18_3_4m___3_x_0_5_x_8_sbhcs___n_9.stl" scale="1 1 1" />
            </geometry></collision></link>
    <link name="socket_button_head_cap_screw_am_b18_3_4m___3_x_0_5_x_8_sbhcs___n_17">
        <inertial>
            <mass value="8.30381e-08" />
            <origin xyz="0.00249142 -7.46853e-13 -2.0375e-12" rpy="0 -0 0" />
            <inertia ixx="1.63366e-13" ixy="0" ixz="0" iyy="7.65861e-13" iyz="0" izz="7.65858e-13" />
        </inertial>
        <visual>
            <origin xyz="-0.00165 0 0" rpy="0 -0 0" />
            <geometry>
                <mesh filename="../meshes/socket_button_head_cap_screw_am_b18_3_4m___3_x_0_5_x_8_sbhcs___n_9.stl" scale="1 1 1" />
            </geometry>
            <material name="0.776471_0.756863_0.737255_0.000000_0.000000">
                <texture />
                <color rgba="0.776471 0.756863 0.737255 1" />
            </material>
        </visual>
    <collision><origin xyz="-0.00165 0 0" rpy="0 -0 0" /><geometry>
                <mesh filename="../meshes/socket_button_head_cap_screw_am_b18_3_4m___3_x_0_5_x_8_sbhcs___n_9.stl" scale="1 1 1" />
            </geometry></collision></link>
    <link name="socket_button_head_cap_screw_am_b18_3_4m___3_x_0_5_x_8_sbhcs___n_2">
        <inertial>
            <mass value="8.30381e-08" />
            <origin xyz="0.00249142 -7.46853e-13 -2.0375e-12" rpy="0 -0 0" />
            <inertia ixx="1.63366e-13" ixy="0" ixz="0" iyy="7.65861e-13" iyz="0" izz="7.65858e-13" />
        </inertial>
        <visual>
            <origin xyz="-0.00165 0 0" rpy="0 -0 0" />
            <geometry>
                <mesh filename="../meshes/socket_button_head_cap_screw_am_b18_3_4m___3_x_0_5_x_8_sbhcs___n_9.stl" scale="1 1 1" />
            </geometry>
            <material name="0.776471_0.756863_0.737255_0.000000_0.000000">
                <texture />
                <color rgba="0.776471 0.756863 0.737255 1" />
            </material>
        </visual>
    <collision><origin xyz="-0.00165 0 0" rpy="0 -0 0" /><geometry>
                <mesh filename="../meshes/socket_button_head_cap_screw_am_b18_3_4m___3_x_0_5_x_8_sbhcs___n_9.stl" scale="1 1 1" />
            </geometry></collision></link>
    <link name="socket_button_head_cap_screw_am_b18_3_4m___3_x_0_5_x_8_sbhcs___n_3">
        <inertial>
            <mass value="8.30381e-08" />
            <origin xyz="0.00249142 -7.46853e-13 -2.0375e-12" rpy="0 -0 0" />
            <inertia ixx="1.63366e-13" ixy="0" ixz="0" iyy="7.65861e-13" iyz="0" izz="7.65858e-13" />
        </inertial>
        <visual>
            <origin xyz="-0.00165 0 0" rpy="0 -0 0" />
            <geometry>
                <mesh filename="../meshes/socket_button_head_cap_screw_am_b18_3_4m___3_x_0_5_x_8_sbhcs___n_9.stl" scale="1 1 1" />
            </geometry>
            <material name="0.776471_0.756863_0.737255_0.000000_0.000000">
                <texture />
                <color rgba="0.776471 0.756863 0.737255 1" />
            </material>
        </visual>
    <collision><origin xyz="-0.00165 0 0" rpy="0 -0 0" /><geometry>
                <mesh filename="../meshes/socket_button_head_cap_screw_am_b18_3_4m___3_x_0_5_x_8_sbhcs___n_9.stl" scale="1 1 1" />
            </geometry></collision></link>
    <link name="socket_button_head_cap_screw_am_b18_3_4m___3_x_0_5_x_8_sbhcs___n_4">
        <inertial>
            <mass value="8.30381e-08" />
            <origin xyz="0.00249142 -7.46853e-13 -2.0375e-12" rpy="0 -0 0" />
            <inertia ixx="1.63366e-13" ixy="0" ixz="0" iyy="7.65861e-13" iyz="0" izz="7.65858e-13" />
        </inertial>
        <visual>
            <origin xyz="-0.00165 0 0" rpy="0 -0 0" />
            <geometry>
                <mesh filename="../meshes/socket_button_head_cap_screw_am_b18_3_4m___3_x_0_5_x_8_sbhcs___n_9.stl" scale="1 1 1" />
            </geometry>
            <material name="0.776471_0.756863_0.737255_0.000000_0.000000">
                <texture />
                <color rgba="0.776471 0.756863 0.737255 1" />
            </material>
        </visual>
    <collision><origin xyz="-0.00165 0 0" rpy="0 -0 0" /><geometry>
                <mesh filename="../meshes/socket_button_head_cap_screw_am_b18_3_4m___3_x_0_5_x_8_sbhcs___n_9.stl" scale="1 1 1" />
            </geometry></collision></link>
    <link name="socket_button_head_cap_screw_am_b18_3_4m___3_x_0_5_x_8_sbhcs___n_5">
        <inertial>
            <mass value="8.30381e-08" />
            <origin xyz="0.00249142 -7.46853e-13 -2.0375e-12" rpy="0 -0 0" />
            <inertia ixx="1.63366e-13" ixy="0" ixz="0" iyy="7.65861e-13" iyz="0" izz="7.65858e-13" />
        </inertial>
        <visual>
            <origin xyz="-0.00165 0 0" rpy="0 -0 0" />
            <geometry>
                <mesh filename="../meshes/socket_button_head_cap_screw_am_b18_3_4m___3_x_0_5_x_8_sbhcs___n_9.stl" scale="1 1 1" />
            </geometry>
            <material name="0.776471_0.756863_0.737255_0.000000_0.000000">
                <texture />
                <color rgba="0.776471 0.756863 0.737255 1" />
            </material>
        </visual>
    <collision><origin xyz="-0.00165 0 0" rpy="0 -0 0" /><geometry>
                <mesh filename="../meshes/socket_button_head_cap_screw_am_b18_3_4m___3_x_0_5_x_8_sbhcs___n_9.stl" scale="1 1 1" />
            </geometry></collision></link>
    <link name="socket_button_head_cap_screw_am_b18_3_4m___3_x_0_5_x_8_sbhcs___n_6">
        <inertial>
            <mass value="8.30381e-08" />
            <origin xyz="0.00239142 -7.46853e-13 -2.0375e-12" rpy="0 -0 0" />
            <inertia ixx="1.63366e-13" ixy="0" ixz="0" iyy="7.65861e-13" iyz="0" izz="7.65858e-13" />
        </inertial>
        <visual>
            <origin xyz="-0.00175 0 0" rpy="0 -0 0" />
            <geometry>
                <mesh filename="../meshes/socket_button_head_cap_screw_am_b18_3_4m___3_x_0_5_x_8_sbhcs___n_9.stl" scale="1 1 1" />
            </geometry>
            <material name="0.776471_0.756863_0.737255_0.000000_0.000000">
                <texture />
                <color rgba="0.776471 0.756863 0.737255 1" />
            </material>
        </visual>
    <collision><origin xyz="-0.00175 0 0" rpy="0 -0 0" /><geometry>
                <mesh filename="../meshes/socket_button_head_cap_screw_am_b18_3_4m___3_x_0_5_x_8_sbhcs___n_9.stl" scale="1 1 1" />
            </geometry></collision></link>
    <link name="socket_button_head_cap_screw_am_b18_3_4m___3_x_0_5_x_8_sbhcs___n_7">
        <inertial>
            <mass value="8.30381e-08" />
            <origin xyz="0.00249142 -7.46853e-13 -2.0375e-12" rpy="0 -0 0" />
            <inertia ixx="1.63366e-13" ixy="0" ixz="0" iyy="7.65861e-13" iyz="0" izz="7.65858e-13" />
        </inertial>
        <visual>
            <origin xyz="-0.00165 0 0" rpy="0 -0 0" />
            <geometry>
                <mesh filename="../meshes/socket_button_head_cap_screw_am_b18_3_4m___3_x_0_5_x_8_sbhcs___n_9.stl" scale="1 1 1" />
            </geometry>
            <material name="0.776471_0.756863_0.737255_0.000000_0.000000">
                <texture />
                <color rgba="0.776471 0.756863 0.737255 1" />
            </material>
        </visual>
    <collision><origin xyz="-0.00165 0 0" rpy="0 -0 0" /><geometry>
                <mesh filename="../meshes/socket_button_head_cap_screw_am_b18_3_4m___3_x_0_5_x_8_sbhcs___n_9.stl" scale="1 1 1" />
            </geometry></collision></link>
    <link name="socket_button_head_cap_screw_am_b18_3_4m___3_x_0_5_x_8_sbhcs___n_8">
        <inertial>
            <mass value="8.30381e-08" />
            <origin xyz="0.00249142 -7.46853e-13 -2.0375e-12" rpy="0 -0 0" />
            <inertia ixx="1.63366e-13" ixy="0" ixz="0" iyy="7.65861e-13" iyz="0" izz="7.65858e-13" />
        </inertial>
        <visual>
            <origin xyz="-0.00165 0 0" rpy="0 -0 0" />
            <geometry>
                <mesh filename="../meshes/socket_button_head_cap_screw_am_b18_3_4m___3_x_0_5_x_8_sbhcs___n_9.stl" scale="1 1 1" />
            </geometry>
            <material name="0.776471_0.756863_0.737255_0.000000_0.000000">
                <texture />
                <color rgba="0.776471 0.756863 0.737255 1" />
            </material>
        </visual>
    <collision><origin xyz="-0.00165 0 0" rpy="0 -0 0" /><geometry>
                <mesh filename="../meshes/socket_button_head_cap_screw_am_b18_3_4m___3_x_0_5_x_8_sbhcs___n_9.stl" scale="1 1 1" />
            </geometry></collision></link>
    <link name="socket_button_head_cap_screw_am_b18_3_4m___3_x_0_5_x_8_sbhcs___n_9">
        <inertial>
            <mass value="8.30381e-08" />
            <origin xyz="0.00249142 -7.46853e-13 -2.0375e-12" rpy="0 -0 0" />
            <inertia ixx="1.63366e-13" ixy="0" ixz="0" iyy="7.65861e-13" iyz="0" izz="7.65858e-13" />
        </inertial>
        <visual>
            <origin xyz="-0.00165 0 0" rpy="0 -0 0" />
            <geometry>
                <mesh filename="../meshes/socket_button_head_cap_screw_am_b18_3_4m___3_x_0_5_x_8_sbhcs___n_9.stl" scale="1 1 1" />
            </geometry>
            <material name="0.776471_0.756863_0.737255_0.000000_0.000000">
                <texture />
                <color rgba="0.776471 0.756863 0.737255 1" />
            </material>
        </visual>
    <collision><origin xyz="-0.00165 0 0" rpy="0 -0 0" /><geometry>
                <mesh filename="../meshes/socket_button_head_cap_screw_am_b18_3_4m___3_x_0_5_x_8_sbhcs___n_9.stl" scale="1 1 1" />
            </geometry></collision></link>
    <link name="socket_button_head_cap_screw_am_b18_3_4m___4_x_0_7_x_20_sbhcs___n_4">
        <inertial>
            <mass value="3.14324e-07" />
            <origin xyz="0.00777147 -8.65078e-13 -1.74829e-12" rpy="0 -0 0" />
            <inertia ixx="9.08088e-13" ixy="0" ixz="0" iyy="1.46918e-11" iyz="0" izz="1.46918e-11" />
        </inertial>
        <visual>
            <origin xyz="-0.0022 0 0" rpy="0 -0 0" />
            <geometry>
                <mesh filename="../meshes/socket_button_head_cap_screw_am_b18_3_4m___4_x_0_7_x_20_sbhcs___n_4.stl" scale="1 1 1" />
            </geometry>
            <material name="0.776471_0.756863_0.737255_0.000000_0.000000">
                <texture />
                <color rgba="0.776471 0.756863 0.737255 1" />
            </material>
        </visual>
    <collision><origin xyz="-0.0022 0 0" rpy="0 -0 0" /><geometry>
                <mesh filename="../meshes/socket_button_head_cap_screw_am_b18_3_4m___4_x_0_7_x_20_sbhcs___n_4.stl" scale="1 1 1" />
            </geometry></collision></link>
    <link name="socket_head_cap_screw_am_b18_3_1m___2_5_x_0_45_x_10_hex_shcs____10nhx">
        <inertial>
            <mass value="8.35744e-08" />
            <origin xyz="0.00242909 2.6097e-19 7.20845e-20" rpy="0 -0 0" />
            <inertia ixx="1.34181e-13" ixy="0" ixz="0" iyy="1.25086e-12" iyz="0" izz="1.25086e-12" />
        </inertial>
        <visual>
            <origin xyz="-0.0025 0 0" rpy="0 -0 0" />
            <geometry>
                <mesh filename="../meshes/socket_head_cap_screw_am_b18_3_1m___2_5_x_0_45_x_10_hex_shcs____10nhx_4.stl" scale="1 1 1" />
            </geometry>
            <material name="0.776471_0.756863_0.737255_0.000000_0.000000">
                <texture />
                <color rgba="0.776471 0.756863 0.737255 1" />
            </material>
        </visual>
    <collision><origin xyz="-0.0025 0 0" rpy="0 -0 0" /><geometry>
                <mesh filename="../meshes/socket_head_cap_screw_am_b18_3_1m___2_5_x_0_45_x_10_hex_shcs____10nhx_4.stl" scale="1 1 1" />
            </geometry></collision></link>
    <link name="socket_head_cap_screw_am_b18_3_1m___2_5_x_0_45_x_10_hex_shcs____10nhx_2">
        <inertial>
            <mass value="8.35744e-08" />
            <origin xyz="0.00242909 2.6097e-19 7.20845e-20" rpy="0 -0 0" />
            <inertia ixx="1.34181e-13" ixy="0" ixz="0" iyy="1.25086e-12" iyz="0" izz="1.25086e-12" />
        </inertial>
        <visual>
            <origin xyz="-0.0025 0 0" rpy="0 -0 0" />
            <geometry>
                <mesh filename="../meshes/socket_head_cap_screw_am_b18_3_1m___2_5_x_0_45_x_10_hex_shcs____10nhx_4.stl" scale="1 1 1" />
            </geometry>
            <material name="0.776471_0.756863_0.737255_0.000000_0.000000">
                <texture />
                <color rgba="0.776471 0.756863 0.737255 1" />
            </material>
        </visual>
    <collision><origin xyz="-0.0025 0 0" rpy="0 -0 0" /><geometry>
                <mesh filename="../meshes/socket_head_cap_screw_am_b18_3_1m___2_5_x_0_45_x_10_hex_shcs____10nhx_4.stl" scale="1 1 1" />
            </geometry></collision></link>
    <link name="socket_head_cap_screw_am_b18_3_1m___2_5_x_0_45_x_10_hex_shcs____10nhx_3">
        <inertial>
            <mass value="8.35744e-08" />
            <origin xyz="0.00242909 2.6097e-19 7.20845e-20" rpy="0 -0 0" />
            <inertia ixx="1.34181e-13" ixy="0" ixz="0" iyy="1.25086e-12" iyz="0" izz="1.25086e-12" />
        </inertial>
        <visual>
            <origin xyz="-0.0025 0 0" rpy="0 -0 0" />
            <geometry>
                <mesh filename="../meshes/socket_head_cap_screw_am_b18_3_1m___2_5_x_0_45_x_10_hex_shcs____10nhx_4.stl" scale="1 1 1" />
            </geometry>
            <material name="0.776471_0.756863_0.737255_0.000000_0.000000">
                <texture />
                <color rgba="0.776471 0.756863 0.737255 1" />
            </material>
        </visual>
    <collision><origin xyz="-0.0025 0 0" rpy="0 -0 0" /><geometry>
                <mesh filename="../meshes/socket_head_cap_screw_am_b18_3_1m___2_5_x_0_45_x_10_hex_shcs____10nhx_4.stl" scale="1 1 1" />
            </geometry></collision></link>
    <link name="socket_head_cap_screw_am_b18_3_1m___2_5_x_0_45_x_10_hex_shcs____10nhx_4">
        <inertial>
            <mass value="8.35744e-08" />
            <origin xyz="0.00242909 2.6097e-19 7.20845e-20" rpy="0 -0 0" />
            <inertia ixx="1.34181e-13" ixy="0" ixz="0" iyy="1.25086e-12" iyz="0" izz="1.25086e-12" />
        </inertial>
        <visual>
            <origin xyz="-0.0025 0 0" rpy="0 -0 0" />
            <geometry>
                <mesh filename="../meshes/socket_head_cap_screw_am_b18_3_1m___2_5_x_0_45_x_10_hex_shcs____10nhx_4.stl" scale="1 1 1" />
            </geometry>
            <material name="0.776471_0.756863_0.737255_0.000000_0.000000">
                <texture />
                <color rgba="0.776471 0.756863 0.737255 1" />
            </material>
        </visual>
    <collision><origin xyz="-0.0025 0 0" rpy="0 -0 0" /><geometry>
                <mesh filename="../meshes/socket_head_cap_screw_am_b18_3_1m___2_5_x_0_45_x_10_hex_shcs____10nhx_4.stl" scale="1 1 1" />
            </geometry></collision></link>
    <link name="socket_head_cap_screw_am_b18_3_1m___3_x_0_5_x_10_hex_shcs____10nhx">
        <inertial>
            <mass value="1.32238e-07" />
            <origin xyz="0.00200023 3.34407e-19 1.45156e-19" rpy="0 -0 0" />
            <inertia ixx="3.35773e-13" ixy="0" ixz="0" iyy="2.1237e-12" iyz="0" izz="2.1237e-12" />
        </inertial>
        <visual>
            <origin xyz="-0.003 0 0" rpy="0 -0 0" />
            <geometry>
                <mesh filename="../meshes/socket_head_cap_screw_am_b18_3_1m___3_x_0_5_x_10_hex_shcs____10nhx_7.stl" scale="1 1 1" />
            </geometry>
            <material name="0.776471_0.756863_0.737255_0.000000_0.000000">
                <texture />
                <color rgba="0.776471 0.756863 0.737255 1" />
            </material>
        </visual>
    <collision><origin xyz="-0.003 0 0" rpy="0 -0 0" /><geometry>
                <mesh filename="../meshes/socket_head_cap_screw_am_b18_3_1m___3_x_0_5_x_10_hex_shcs____10nhx_7.stl" scale="1 1 1" />
            </geometry></collision></link>
    <link name="socket_head_cap_screw_am_b18_3_1m___3_x_0_5_x_10_hex_shcs____10nhx_1">
        <inertial>
            <mass value="1.32238e-07" />
            <origin xyz="0.00200023 3.34407e-19 1.45156e-19" rpy="0 -0 0" />
            <inertia ixx="3.35773e-13" ixy="0" ixz="0" iyy="2.1237e-12" iyz="0" izz="2.1237e-12" />
        </inertial>
        <visual>
            <origin xyz="-0.003 0 0" rpy="0 -0 0" />
            <geometry>
                <mesh filename="../meshes/socket_head_cap_screw_am_b18_3_1m___3_x_0_5_x_10_hex_shcs____10nhx_7.stl" scale="1 1 1" />
            </geometry>
            <material name="0.776471_0.756863_0.737255_0.000000_0.000000">
                <texture />
                <color rgba="0.776471 0.756863 0.737255 1" />
            </material>
        </visual>
    <collision><origin xyz="-0.003 0 0" rpy="0 -0 0" /><geometry>
                <mesh filename="../meshes/socket_head_cap_screw_am_b18_3_1m___3_x_0_5_x_10_hex_shcs____10nhx_7.stl" scale="1 1 1" />
            </geometry></collision></link>
    <link name="socket_head_cap_screw_am_b18_3_1m___3_x_0_5_x_10_hex_shcs____10nhx_2">
        <inertial>
            <mass value="1.32238e-07" />
            <origin xyz="0.00200023 3.34407e-19 1.45156e-19" rpy="0 -0 0" />
            <inertia ixx="3.35773e-13" ixy="0" ixz="0" iyy="2.1237e-12" iyz="0" izz="2.1237e-12" />
        </inertial>
        <visual>
            <origin xyz="-0.003 0 0" rpy="0 -0 0" />
            <geometry>
                <mesh filename="../meshes/socket_head_cap_screw_am_b18_3_1m___3_x_0_5_x_10_hex_shcs____10nhx_7.stl" scale="1 1 1" />
            </geometry>
            <material name="0.776471_0.756863_0.737255_0.000000_0.000000">
                <texture />
                <color rgba="0.776471 0.756863 0.737255 1" />
            </material>
        </visual>
    <collision><origin xyz="-0.003 0 0" rpy="0 -0 0" /><geometry>
                <mesh filename="../meshes/socket_head_cap_screw_am_b18_3_1m___3_x_0_5_x_10_hex_shcs____10nhx_7.stl" scale="1 1 1" />
            </geometry></collision></link>
    <link name="socket_head_cap_screw_am_b18_3_1m___3_x_0_5_x_10_hex_shcs____10nhx_3">
        <inertial>
            <mass value="1.32238e-07" />
            <origin xyz="0.00200023 3.34407e-19 1.45156e-19" rpy="0 -0 0" />
            <inertia ixx="3.35773e-13" ixy="0" ixz="0" iyy="2.1237e-12" iyz="0" izz="2.1237e-12" />
        </inertial>
        <visual>
            <origin xyz="-0.003 0 0" rpy="0 -0 0" />
            <geometry>
                <mesh filename="../meshes/socket_head_cap_screw_am_b18_3_1m___3_x_0_5_x_10_hex_shcs____10nhx_7.stl" scale="1 1 1" />
            </geometry>
            <material name="0.776471_0.756863_0.737255_0.000000_0.000000">
                <texture />
                <color rgba="0.776471 0.756863 0.737255 1" />
            </material>
        </visual>
    <collision><origin xyz="-0.003 0 0" rpy="0 -0 0" /><geometry>
                <mesh filename="../meshes/socket_head_cap_screw_am_b18_3_1m___3_x_0_5_x_10_hex_shcs____10nhx_7.stl" scale="1 1 1" />
            </geometry></collision></link>
    <link name="socket_head_cap_screw_am_b18_3_1m___3_x_0_5_x_10_hex_shcs____10nhx_4">
        <inertial>
            <mass value="1.32238e-07" />
            <origin xyz="0.00200023 3.34407e-19 1.45156e-19" rpy="0 -0 0" />
            <inertia ixx="3.35773e-13" ixy="0" ixz="0" iyy="2.1237e-12" iyz="0" izz="2.1237e-12" />
        </inertial>
        <visual>
            <origin xyz="-0.003 0 0" rpy="0 -0 0" />
            <geometry>
                <mesh filename="../meshes/socket_head_cap_screw_am_b18_3_1m___3_x_0_5_x_10_hex_shcs____10nhx_7.stl" scale="1 1 1" />
            </geometry>
            <material name="0.776471_0.756863_0.737255_0.000000_0.000000">
                <texture />
                <color rgba="0.776471 0.756863 0.737255 1" />
            </material>
        </visual>
    <collision><origin xyz="-0.003 0 0" rpy="0 -0 0" /><geometry>
                <mesh filename="../meshes/socket_head_cap_screw_am_b18_3_1m___3_x_0_5_x_10_hex_shcs____10nhx_7.stl" scale="1 1 1" />
            </geometry></collision></link>
    <link name="socket_head_cap_screw_am_b18_3_1m___3_x_0_5_x_10_hex_shcs____10nhx_5">
        <inertial>
            <mass value="1.32238e-07" />
            <origin xyz="0.00200023 3.34407e-19 1.45156e-19" rpy="0 -0 0" />
            <inertia ixx="3.35773e-13" ixy="0" ixz="0" iyy="2.1237e-12" iyz="0" izz="2.1237e-12" />
        </inertial>
        <visual>
            <origin xyz="-0.003 0 0" rpy="0 -0 0" />
            <geometry>
                <mesh filename="../meshes/socket_head_cap_screw_am_b18_3_1m___3_x_0_5_x_10_hex_shcs____10nhx_7.stl" scale="1 1 1" />
            </geometry>
            <material name="0.776471_0.756863_0.737255_0.000000_0.000000">
                <texture />
                <color rgba="0.776471 0.756863 0.737255 1" />
            </material>
        </visual>
    <collision><origin xyz="-0.003 0 0" rpy="0 -0 0" /><geometry>
                <mesh filename="../meshes/socket_head_cap_screw_am_b18_3_1m___3_x_0_5_x_10_hex_shcs____10nhx_7.stl" scale="1 1 1" />
            </geometry></collision></link>
    <link name="socket_head_cap_screw_am_b18_3_1m___3_x_0_5_x_10_hex_shcs____10nhx_6">
        <inertial>
            <mass value="1.32238e-07" />
            <origin xyz="0.00200023 3.34407e-19 1.45156e-19" rpy="0 -0 0" />
            <inertia ixx="3.35773e-13" ixy="0" ixz="0" iyy="2.1237e-12" iyz="0" izz="2.1237e-12" />
        </inertial>
        <visual>
            <origin xyz="-0.003 0 0" rpy="0 -0 0" />
            <geometry>
                <mesh filename="../meshes/socket_head_cap_screw_am_b18_3_1m___3_x_0_5_x_10_hex_shcs____10nhx_7.stl" scale="1 1 1" />
            </geometry>
            <material name="0.776471_0.756863_0.737255_0.000000_0.000000">
                <texture />
                <color rgba="0.776471 0.756863 0.737255 1" />
            </material>
        </visual>
    <collision><origin xyz="-0.003 0 0" rpy="0 -0 0" /><geometry>
                <mesh filename="../meshes/socket_head_cap_screw_am_b18_3_1m___3_x_0_5_x_10_hex_shcs____10nhx_7.stl" scale="1 1 1" />
            </geometry></collision></link>
    <link name="socket_head_cap_screw_am_b18_3_1m___3_x_0_5_x_10_hex_shcs____10nhx_7">
        <inertial>
            <mass value="1.32238e-07" />
            <origin xyz="0.00190023 3.34407e-19 1.45156e-19" rpy="0 -0 0" />
            <inertia ixx="3.35773e-13" ixy="0" ixz="0" iyy="2.1237e-12" iyz="0" izz="2.1237e-12" />
        </inertial>
        <visual>
            <origin xyz="-0.0031 0 0" rpy="0 -0 0" />
            <geometry>
                <mesh filename="../meshes/socket_head_cap_screw_am_b18_3_1m___3_x_0_5_x_10_hex_shcs____10nhx_7.stl" scale="1 1 1" />
            </geometry>
            <material name="0.776471_0.756863_0.737255_0.000000_0.000000">
                <texture />
                <color rgba="0.776471 0.756863 0.737255 1" />
            </material>
        </visual>
    <collision><origin xyz="-0.0031 0 0" rpy="0 -0 0" /><geometry>
                <mesh filename="../meshes/socket_head_cap_screw_am_b18_3_1m___3_x_0_5_x_10_hex_shcs____10nhx_7.stl" scale="1 1 1" />
            </geometry></collision></link>
    <link name="socket_head_cap_screw_am_b18_3_1m___3_x_0_5_x_20_hex_shcs____20nhx">
        <inertial>
            <mass value="2.02924e-07" />
            <origin xyz="0.00651139 4.71298e-19 3.08154e-19" rpy="0 -0 0" />
            <inertia ixx="4.15295e-13" ixy="0" ixz="0" iyy="1.04786e-11" iyz="0" izz="1.04786e-11" />
        </inertial>
        <visual>
            <origin xyz="-0.003 0 0" rpy="0 -0 0" />
            <geometry>
                <mesh filename="../meshes/socket_head_cap_screw_am_b18_3_1m___3_x_0_5_x_20_hex_shcs____20nhx_3.stl" scale="1 1 1" />
            </geometry>
            <material name="0.776471_0.756863_0.737255_0.000000_0.000000">
                <texture />
                <color rgba="0.776471 0.756863 0.737255 1" />
            </material>
        </visual>
    <collision><origin xyz="-0.003 0 0" rpy="0 -0 0" /><geometry>
                <mesh filename="../meshes/socket_head_cap_screw_am_b18_3_1m___3_x_0_5_x_20_hex_shcs____20nhx_3.stl" scale="1 1 1" />
            </geometry></collision></link>
    <link name="socket_head_cap_screw_am_b18_3_1m___3_x_0_5_x_20_hex_shcs____20nhx_1">
        <inertial>
            <mass value="2.02924e-07" />
            <origin xyz="0.00651139 4.71298e-19 3.08154e-19" rpy="0 -0 0" />
            <inertia ixx="4.15295e-13" ixy="0" ixz="0" iyy="1.04786e-11" iyz="0" izz="1.04786e-11" />
        </inertial>
        <visual>
            <origin xyz="-0.003 0 0" rpy="0 -0 0" />
            <geometry>
                <mesh filename="../meshes/socket_head_cap_screw_am_b18_3_1m___3_x_0_5_x_20_hex_shcs____20nhx_3.stl" scale="1 1 1" />
            </geometry>
            <material name="0.776471_0.756863_0.737255_0.000000_0.000000">
                <texture />
                <color rgba="0.776471 0.756863 0.737255 1" />
            </material>
        </visual>
    <collision><origin xyz="-0.003 0 0" rpy="0 -0 0" /><geometry>
                <mesh filename="../meshes/socket_head_cap_screw_am_b18_3_1m___3_x_0_5_x_20_hex_shcs____20nhx_3.stl" scale="1 1 1" />
            </geometry></collision></link>
    <link name="socket_head_cap_screw_am_b18_3_1m___3_x_0_5_x_20_hex_shcs____20nhx_2">
        <inertial>
            <mass value="2.02924e-07" />
            <origin xyz="0.00651139 4.71298e-19 3.08154e-19" rpy="0 -0 0" />
            <inertia ixx="4.15295e-13" ixy="0" ixz="0" iyy="1.04786e-11" iyz="0" izz="1.04786e-11" />
        </inertial>
        <visual>
            <origin xyz="-0.003 0 0" rpy="0 -0 0" />
            <geometry>
                <mesh filename="../meshes/socket_head_cap_screw_am_b18_3_1m___3_x_0_5_x_20_hex_shcs____20nhx_3.stl" scale="1 1 1" />
            </geometry>
            <material name="0.776471_0.756863_0.737255_0.000000_0.000000">
                <texture />
                <color rgba="0.776471 0.756863 0.737255 1" />
            </material>
        </visual>
    <collision><origin xyz="-0.003 0 0" rpy="0 -0 0" /><geometry>
                <mesh filename="../meshes/socket_head_cap_screw_am_b18_3_1m___3_x_0_5_x_20_hex_shcs____20nhx_3.stl" scale="1 1 1" />
            </geometry></collision></link>
    <link name="socket_head_cap_screw_am_b18_3_1m___3_x_0_5_x_20_hex_shcs____20nhx_3">
        <inertial>
            <mass value="2.02924e-07" />
            <origin xyz="0.00651139 4.71298e-19 3.08154e-19" rpy="0 -0 0" />
            <inertia ixx="4.15295e-13" ixy="0" ixz="0" iyy="1.04786e-11" iyz="0" izz="1.04786e-11" />
        </inertial>
        <visual>
            <origin xyz="-0.003 0 0" rpy="0 -0 0" />
            <geometry>
                <mesh filename="../meshes/socket_head_cap_screw_am_b18_3_1m___3_x_0_5_x_20_hex_shcs____20nhx_3.stl" scale="1 1 1" />
            </geometry>
            <material name="0.776471_0.756863_0.737255_0.000000_0.000000">
                <texture />
                <color rgba="0.776471 0.756863 0.737255 1" />
            </material>
        </visual>
    <collision><origin xyz="-0.003 0 0" rpy="0 -0 0" /><geometry>
                <mesh filename="../meshes/socket_head_cap_screw_am_b18_3_1m___3_x_0_5_x_20_hex_shcs____20nhx_3.stl" scale="1 1 1" />
            </geometry></collision></link>
    <link name="socket_head_cap_screw_am_b18_3_1m___3_x_0_5_x_8_hex_shcs____8nhx">
        <inertial>
            <mass value="1.18101e-07" />
            <origin xyz="0.00116821 4.3395e-19 1.07758e-19" rpy="0 -0 0" />
            <inertia ixx="3.19869e-13" ixy="0" ixz="0" iyy="1.34621e-12" iyz="0" izz="1.34621e-12" />
        </inertial>
        <visual>
            <origin xyz="-0.003 0 0" rpy="0 -0 0" />
            <geometry>
                <mesh filename="../meshes/socket_head_cap_screw_am_b18_3_1m___3_x_0_5_x_8_hex_shcs____8nhx_3.stl" scale="1 1 1" />
            </geometry>
            <material name="0.776471_0.756863_0.737255_0.000000_0.000000">
                <texture />
                <color rgba="0.776471 0.756863 0.737255 1" />
            </material>
        </visual>
    <collision><origin xyz="-0.003 0 0" rpy="0 -0 0" /><geometry>
                <mesh filename="../meshes/socket_head_cap_screw_am_b18_3_1m___3_x_0_5_x_8_hex_shcs____8nhx_3.stl" scale="1 1 1" />
            </geometry></collision></link>
    <link name="socket_head_cap_screw_am_b18_3_1m___3_x_0_5_x_8_hex_shcs____8nhx_1">
        <inertial>
            <mass value="1.18101e-07" />
            <origin xyz="0.00116821 4.3395e-19 1.07758e-19" rpy="0 -0 0" />
            <inertia ixx="3.19869e-13" ixy="0" ixz="0" iyy="1.34621e-12" iyz="0" izz="1.34621e-12" />
        </inertial>
        <visual>
            <origin xyz="-0.003 0 0" rpy="0 -0 0" />
            <geometry>
                <mesh filename="../meshes/socket_head_cap_screw_am_b18_3_1m___3_x_0_5_x_8_hex_shcs____8nhx_3.stl" scale="1 1 1" />
            </geometry>
            <material name="0.776471_0.756863_0.737255_0.000000_0.000000">
                <texture />
                <color rgba="0.776471 0.756863 0.737255 1" />
            </material>
        </visual>
    <collision><origin xyz="-0.003 0 0" rpy="0 -0 0" /><geometry>
                <mesh filename="../meshes/socket_head_cap_screw_am_b18_3_1m___3_x_0_5_x_8_hex_shcs____8nhx_3.stl" scale="1 1 1" />
            </geometry></collision></link>
    <link name="socket_head_cap_screw_am_b18_3_1m___3_x_0_5_x_8_hex_shcs____8nhx_2">
        <inertial>
            <mass value="1.18101e-07" />
            <origin xyz="0.00116821 4.3395e-19 1.07758e-19" rpy="0 -0 0" />
            <inertia ixx="3.19869e-13" ixy="0" ixz="0" iyy="1.34621e-12" iyz="0" izz="1.34621e-12" />
        </inertial>
        <visual>
            <origin xyz="-0.003 0 0" rpy="0 -0 0" />
            <geometry>
                <mesh filename="../meshes/socket_head_cap_screw_am_b18_3_1m___3_x_0_5_x_8_hex_shcs____8nhx_3.stl" scale="1 1 1" />
            </geometry>
            <material name="0.776471_0.756863_0.737255_0.000000_0.000000">
                <texture />
                <color rgba="0.776471 0.756863 0.737255 1" />
            </material>
        </visual>
    <collision><origin xyz="-0.003 0 0" rpy="0 -0 0" /><geometry>
                <mesh filename="../meshes/socket_head_cap_screw_am_b18_3_1m___3_x_0_5_x_8_hex_shcs____8nhx_3.stl" scale="1 1 1" />
            </geometry></collision></link>
    <link name="socket_head_cap_screw_am_b18_3_1m___3_x_0_5_x_8_hex_shcs____8nhx_3">
        <inertial>
            <mass value="1.18101e-07" />
            <origin xyz="0.00116821 4.3395e-19 1.07758e-19" rpy="0 -0 0" />
            <inertia ixx="3.19869e-13" ixy="0" ixz="0" iyy="1.34621e-12" iyz="0" izz="1.34621e-12" />
        </inertial>
        <visual>
            <origin xyz="-0.003 0 0" rpy="0 -0 0" />
            <geometry>
                <mesh filename="../meshes/socket_head_cap_screw_am_b18_3_1m___3_x_0_5_x_8_hex_shcs____8nhx_3.stl" scale="1 1 1" />
            </geometry>
            <material name="0.776471_0.756863_0.737255_0.000000_0.000000">
                <texture />
                <color rgba="0.776471 0.756863 0.737255 1" />
            </material>
        </visual>
    <collision><origin xyz="-0.003 0 0" rpy="0 -0 0" /><geometry>
                <mesh filename="../meshes/socket_head_cap_screw_am_b18_3_1m___3_x_0_5_x_8_hex_shcs____8nhx_3.stl" scale="1 1 1" />
            </geometry></collision></link>
    <link name="socket_head_cap_screw_am_b18_3_1m___6_x_1_0_x_40_hex_shcs____24nhx">
        <inertial>
            <mass value="1.51724e-06" />
            <origin xyz="0.0141424 1.93719e-19 -7.28858e-20" rpy="0 -0 0" />
            <inertia ixx="1.05749e-11" ixy="0" ixz="0" iyy="3.04699e-10" iyz="0" izz="3.04699e-10" />
        </inertial>
        <visual>
            <origin xyz="-0.006 0 0" rpy="0 -0 0" />
            <geometry>
                <mesh filename="../meshes/socket_head_cap_screw_am_b18_3_1m___6_x_1_0_x_40_hex_shcs____24nhx.stl" scale="1 1 1" />
            </geometry>
            <material name="0.776471_0.756863_0.737255_0.000000_0.000000">
                <texture />
                <color rgba="0.776471 0.756863 0.737255 1" />
            </material>
        </visual>
    <collision><origin xyz="-0.006 0 0" rpy="0 -0 0" /><geometry>
                <mesh filename="../meshes/socket_head_cap_screw_am_b18_3_1m___6_x_1_0_x_40_hex_shcs____24nhx.stl" scale="1 1 1" />
            </geometry></collision></link>
    <link name="triplate_dual">
        <inertial>
            <mass value="7.80508e-06" />
            <origin xyz="0.021735 -0.00823235 0.000358919" rpy="0 -0 0" />
            <inertia ixx="5.71119e-10" ixy="1.10667e-10" ixz="1.2085e-11" iyy="2.19048e-09" iyz="-5.19697e-12" izz="1.72559e-09" />
        </inertial>
        <visual>
            <origin xyz="0.0183148 0.0535 -0.155744" rpy="0 -0 0" />
            <geometry>
                <mesh filename="../meshes/triplate_dual.stl" scale="1 1 1" />
            </geometry>
            <material name="0.298039_0.298039_0.298039_0.000000_0.000000">
                <texture />
                <color rgba="0.298039 0.298039 0.298039 1" />
            </material>
        </visual>
    <collision><origin xyz="0.0183148 0.0535 -0.155744" rpy="0 -0 0" /><geometry>
                <mesh filename="../meshes/triplate_dual.stl" scale="1 1 1" />
            </geometry></collision></link>
    <link name="upper_shank_140">
        <inertial>
            <mass value="2.63723e-05" />
            <origin xyz="0.0509536 -1.83701e-05 -0.00798866" rpy="0 -0 0" />
            <inertia ixx="1.29113e-09" ixy="-7.99265e-12" ixz="-1.00146e-09" iyy="7.94528e-08" iyz="2.36742e-13" izz="7.97893e-08" />
        </inertial>
        <visual>
            <origin xyz="-0.05 0.23 -0.015" rpy="0 -0 0" />
            <geometry>
                <mesh filename="../meshes/upper_shank_140.stl" scale="1 1 1" />
            </geometry>
            <material name="0.909804_0.443137_0.031373_0.000000_0.000000">
                <texture />
                <color rgba="0.909804 0.443137 0.0313726 1" />
            </material>
        </visual>
    <collision><origin xyz="-0.05 0.23 -0.015" rpy="0 -0 0" /><geometry>
                <mesh filename="../meshes/upper_shank_140.stl" scale="1 1 1" />
            </geometry></collision></link>
    <joint name="fastened_10_0" type="fixed">
        <origin xyz="-0.0175 0.0008 -5.55112e-17" rpy="3.14159 1.22954e-15 -1.5708" />
        <axis xyz="1 0 0" />
        <parent link="28byj_48_5v_stepper_motor" />
        <child link="socket_button_head_cap_screw_am_b18_3_4m___3_x_0_5_x_6_sbhcs___n" />
    </joint>
    <joint name="fastened_11_0" type="fixed">
        <origin xyz="0.003 0 -2.77556e-17" rpy="-3.14159 -1.02305e-22 -3.14159" />
        <axis xyz="1 0 0" />
        <parent link="robot_belt_arm_stabilizer___logigate" />
        <child link="socket_head_cap_screw_am_b18_3_1m___3_x_0_5_x_8_hex_shcs____8nhx" />
    </joint>
    <joint name="fastened_12_0" type="fixed">
        <origin xyz="0.003 0.046 0" rpy="-3.14159 -1.02305e-22 -3.14159" />
        <axis xyz="1 0 0" />
        <parent link="robot_belt_arm_stabilizer___logigate" />
        <child link="socket_head_cap_screw_am_b18_3_1m___3_x_0_5_x_8_hex_shcs____8nhx_2" />
    </joint>
    <joint name="fastened_13_0" type="fixed">
        <origin xyz="0.003 -1.38778e-17 0.01" rpy="-3.14159 -1.02305e-22 -3.14159" />
        <axis xyz="1 0 0" />
        <parent link="robot_belt_arm_stabilizer___logigate" />
        <child link="socket_head_cap_screw_am_b18_3_1m___3_x_0_5_x_8_hex_shcs____8nhx_1" />
    </joint>
    <joint name="fastened_14_0" type="fixed">
        <origin xyz="0.003 0.046 0.01" rpy="-3.14159 -1.02305e-22 -3.14159" />
        <axis xyz="1 0 0" />
        <parent link="robot_belt_arm_stabilizer___logigate" />
        <child link="socket_head_cap_screw_am_b18_3_1m___3_x_0_5_x_8_hex_shcs____8nhx_3" />
    </joint>
    <joint name="fastened_15_0" type="fixed">
        <origin xyz="-0.0035 -0.046 -5.55112e-17" rpy="1.5708 -1.67804e-16 -1.09752e-16" />
        <axis xyz="1 0 0" />
        <parent link="robot_belt_arm_endstop___mymod" />
        <child link="socket_button_head_cap_screw_am_b18_3_4m___3_x_0_5_x_8_sbhcs___n_2" />
    </joint>
    <joint name="fastened_16_0" type="fixed">
        <origin xyz="-0.0035 -0.046 -0.01" rpy="1.5708 -1.67804e-16 -1.09752e-16" />
        <axis xyz="1 0 0" />
        <parent link="robot_belt_arm_endstop___mymod" />
        <child link="socket_button_head_cap_screw_am_b18_3_4m___3_x_0_5_x_8_sbhcs___n_10" />
    </joint>
    <joint name="fastened_17_0" type="fixed">
        <origin xyz="-0.0035 6.93889e-18 -0.01" rpy="1.5708 -1.67804e-16 -1.09752e-16" />
        <axis xyz="1 0 0" />
        <parent link="robot_belt_arm_endstop___mymod" />
        <child link="socket_button_head_cap_screw_am_b18_3_4m___3_x_0_5_x_8_sbhcs___n_8" />
    </joint>
    <joint name="fastened_18_0" type="fixed">
        <origin xyz="-0.0035 1.38778e-17 -8.32667e-17" rpy="1.5708 -6.1742e-15 -6.37132e-15" />
        <axis xyz="1 0 0" />
        <parent link="robot_belt_arm_endstop___mymod" />
        <child link="socket_button_head_cap_screw_am_b18_3_4m___3_x_0_5_x_8_sbhcs___n_1" />
    </joint>
    <joint name="fastened_19_0" type="fixed">
        <origin xyz="0.0135 0.0135 0.0045" rpy="0 1.5708 1.5708" />
        <axis xyz="1 0 0" />
        <parent link="robot_belt_arm_main_body_v2______mymod" />
        <child link="socket_button_head_cap_screw_am_b18_3_4m___3_x_0_5_x_8_sbhcs___n_13" />
    </joint>
    <joint name="fastened_1_0" type="fixed">
        <origin xyz="0.0999887 -0.101005 -0.0632" rpy="0 -0 0" />
        <axis xyz="1 0 0" />
        <parent link="robot_belt_arm_basering" />
        <child link="robot_belt_arm_leg" />
    </joint>
    <joint name="fastened_20_0" type="fixed">
        <origin xyz="0.0135 -0.0135 0.0045" rpy="0 1.5708 1.5708" />
        <axis xyz="1 0 0" />
        <parent link="robot_belt_arm_main_body_v2______mymod" />
        <child link="socket_button_head_cap_screw_am_b18_3_4m___3_x_0_5_x_8_sbhcs___n_15" />
    </joint>
    <joint name="fastened_21_0" type="fixed">
        <origin xyz="-0.0135 -0.0135 0.0045" rpy="0 1.5708 1.5708" />
        <axis xyz="1 0 0" />
        <parent link="robot_belt_arm_main_body_v2______mymod" />
        <child link="socket_button_head_cap_screw_am_b18_3_4m___3_x_0_5_x_8_sbhcs___n_3" />
    </joint>
    <joint name="fastened_22_0" type="fixed">
        <origin xyz="-0.0135 0.0135 0.0045" rpy="0 1.5708 1.5708" />
        <axis xyz="1 0 0" />
        <parent link="robot_belt_arm_main_body_v2______mymod" />
        <child link="socket_button_head_cap_screw_am_b18_3_4m___3_x_0_5_x_8_sbhcs___n_17" />
    </joint>
    <joint name="fastened_23_0" type="fixed">
        <origin xyz="0.00999996 0.004 -5.55112e-17" rpy="-7.9111e-17 -1.61837e-16 1.5708" />
        <axis xyz="1 0 0" />
        <parent link="robot_belt_arm_gear_body_1" />
        <child link="socket_head_cap_screw_am_b18_3_1m___3_x_0_5_x_20_hex_shcs____20nhx_1" />
    </joint>
    <joint name="fastened_24_0" type="fixed">
        <origin xyz="-2.77556e-17 0.004 -0.01" rpy="-1.62115e-16 -1.33819e-16 1.5708" />
        <axis xyz="1 0 0" />
        <parent link="robot_belt_arm_gear_body_1" />
        <child link="socket_head_cap_screw_am_b18_3_1m___3_x_0_5_x_20_hex_shcs____20nhx_2" />
    </joint>
    <joint name="fastened_25_0" type="fixed">
        <origin xyz="-0.01 0.004 -2.77556e-17" rpy="-2.75873e-15 -1.50918e-15 1.5708" />
        <axis xyz="1 0 0" />
        <parent link="robot_belt_arm_gear_body_1" />
        <child link="socket_head_cap_screw_am_b18_3_1m___3_x_0_5_x_20_hex_shcs____20nhx" />
    </joint>
    <joint name="fastened_26_0" type="fixed">
        <origin xyz="-2.77556e-17 0.004 0.01" rpy="1.5708 -6.05072e-15 1.5708" />
        <axis xyz="1 0 0" />
        <parent link="robot_belt_arm_gear_body_1" />
        <child link="socket_head_cap_screw_am_b18_3_1m___3_x_0_5_x_20_hex_shcs____20nhx_3" />
    </joint>
    <joint name="fastened_27_0" type="fixed">
        <origin xyz="-0.002 -0.019 -0.001488" rpy="0 -1.5708 4.71239" />
        <axis xyz="0 -1 0" />
        <parent link="robot_belt_arm_endstop___mymod" />
        <child link="limit_switch" />
    </joint>
    <joint name="fastened_28_0" type="fixed">
        <origin xyz="-0.0359195 -0.0632203 0.02135" rpy="0 -0 6.16298e-33" />
        <axis xyz="0 -1 0" />
        <parent link="robot_belt_arm_socket_v2" />
        <child link="limit_switch_1" />
    </joint>
    <joint name="fastened_2_0" type="fixed">
        <origin xyz="0.151989 -0.0490051 -0.0632" rpy="0 -0 1.5708" />
        <axis xyz="1 0 0" />
        <parent link="robot_belt_arm_basering" />
        <child link="robot_belt_arm_leg_1" />
    </joint>
    <joint name="fastened_30_0" type="fixed">
        <origin xyz="-0.053 -0.0491602 0.005" rpy="0 1.5708 -0" />
        <axis xyz="1 0 0" />
        <parent link="robot_belt_arm_socket_v2" />
        <child link="socket_head_cap_screw_am_b18_3_1m___3_x_0_5_x_10_hex_shcs____10nhx_4" />
    </joint>
    <joint name="fastened_31_0" type="fixed">
        <origin xyz="-0.0155 -0.022 0.0425" rpy="3.11173e-31 2.0095e-31 -1.5708" />
        <axis xyz="1 0 0" />
        <parent link="robot_belt_arm_main_body_v2______mymod" />
        <child link="socket_button_head_cap_screw_am_b18_3_4m___3_x_0_5_x_8_sbhcs___n_4" />
    </joint>
    <joint name="fastened_32_0" type="fixed">
        <origin xyz="0.0155 -0.022 0.0425" rpy="9.89967e-31 2.12041e-31 -1.5708" />
        <axis xyz="1 0 0" />
        <parent link="robot_belt_arm_main_body_v2______mymod" />
        <child link="socket_button_head_cap_screw_am_b18_3_4m___3_x_0_5_x_8_sbhcs___n_9" />
    </joint>
    <joint name="fastened_33_0" type="fixed">
        <origin xyz="-0.0155 -0.022 0.0115" rpy="-3.04483e-16 -5.16486e-16 -1.5708" />
        <axis xyz="1 0 0" />
        <parent link="robot_belt_arm_main_body_v2______mymod" />
        <child link="socket_button_head_cap_screw_am_b18_3_4m___3_x_0_5_x_8_sbhcs___n_6" />
    </joint>
    <joint name="fastened_34_0" type="fixed">
        <origin xyz="0.0155 0.02 0.0425" rpy="-3.14159 -4.21932e-16 1.5708" />
        <axis xyz="1 0 0" />
        <parent link="robot_belt_arm_main_body_v2______mymod" />
        <child link="socket_button_head_cap_screw_am_b18_3_4m___3_x_0_5_x_8_sbhcs___n_12" />
    </joint>
    <joint name="fastened_35_0" type="fixed">
        <origin xyz="-0.0155 0.022 0.0425" rpy="8.78734e-32 1.07211e-32 1.5708" />
        <axis xyz="1 0 0" />
        <parent link="robot_belt_arm_main_body_v2______mymod" />
        <child link="socket_button_head_cap_screw_am_b18_3_4m___3_x_0_5_x_8_sbhcs___n_7" />
    </joint>
    <joint name="fastened_36_0" type="fixed">
        <origin xyz="0.0155 0.022 0.0115" rpy="2.04623e-30 3.82837e-31 1.5708" />
        <axis xyz="1 0 0" />
        <parent link="robot_belt_arm_main_body_v2______mymod" />
        <child link="socket_button_head_cap_screw_am_b18_3_4m___3_x_0_5_x_8_sbhcs___n_14" />
    </joint>
    <joint name="fastened_37_0" type="fixed">
        <origin xyz="-0.0155 0.022 0.0115" rpy="1.82277e-30 2.5794e-31 1.5708" />
        <axis xyz="1 0 0" />
        <parent link="robot_belt_arm_main_body_v2______mymod" />
        <child link="socket_button_head_cap_screw_am_b18_3_4m___3_x_0_5_x_8_sbhcs___n" />
    </joint>
    <joint name="fastened_38_0" type="fixed">
        <origin xyz="0.0155 -0.022 0.0115" rpy="3.14159 -3.75105e-16 -1.5708" />
        <axis xyz="1 0 0" />
        <parent link="robot_belt_arm_main_body_v2______mymod" />
        <child link="socket_button_head_cap_screw_am_b18_3_4m___3_x_0_5_x_8_sbhcs___n_11" />
    </joint>
    <joint name="fastened_39_0" type="fixed">
        <origin xyz="-0.0037 -0.019 -0.001488" rpy="1.5708 -6.22641e-15 -6.31911e-15" />
        <axis xyz="1 0 0" />
        <parent link="robot_belt_arm_endstop___mymod" />
        <child link="socket_head_cap_screw_am_b18_3_1m___2_5_x_0_45_x_10_hex_shcs____10nhx_2" />
    </joint>
    <joint name="fastened_3_0" type="fixed">
        <origin xyz="0.0999887 0.00299489 -0.0632" rpy="0 -0 3.14159" />
        <axis xyz="1 0 0" />
        <parent link="robot_belt_arm_basering" />
        <child link="robot_belt_arm_leg_2" />
    </joint>
    <joint name="fastened_40_0" type="fixed">
        <origin xyz="-0.0037 -0.0255 -0.001488" rpy="1.5708 2.498e-16 2.31645e-16" />
        <axis xyz="1 0 0" />
        <parent link="robot_belt_arm_endstop___mymod" />
        <child link="socket_head_cap_screw_am_b18_3_1m___2_5_x_0_45_x_10_hex_shcs____10nhx_3" />
    </joint>
    <joint name="fastened_41_0" type="fixed">
        <origin xyz="-0.00586899 -0.033 0.0271388" rpy="6.47909e-23 3.75144e-23 1.5708" />
        <axis xyz="1 0 0" />
        <parent link="robot_belt_arm_endstop___mymod" />
        <child link="socket_head_cap_screw_am_b18_3_1m___2_5_x_0_45_x_10_hex_shcs____10nhx_4" />
    </joint>
    <joint name="fastened_42_0" type="fixed">
        <origin xyz="-0.0104652 -0.033 0.031735" rpy="6.47909e-23 3.75144e-23 1.5708" />
        <axis xyz="1 0 0" />
        <parent link="robot_belt_arm_endstop___mymod" />
        <child link="socket_head_cap_screw_am_b18_3_1m___2_5_x_0_45_x_10_hex_shcs____10nhx" />
    </joint>
    <joint name="fastened_43_0" type="fixed">
        <origin xyz="0.0097465 -2.77556e-17 -5.20417e-18" rpy="0 1.5708 4.07471e-17" />
        <axis xyz="0 0 -1" />
        <parent link="socket_head_cap_screw_am_b18_3_1m___2_5_x_0_45_x_10_hex_shcs____10nhx_3" />
        <child link="hex_nut_style_1_am_b18_2_4_1m___hex_nut__style_1___m2_5_x_0_45___d_n_5" />
    </joint>
    <joint name="fastened_44_0" type="fixed">
        <origin xyz="0.0097465 -5.55112e-17 0" rpy="0 -1.5708 -3.61459e-30" />
        <axis xyz="0 0 -1" />
        <parent link="socket_head_cap_screw_am_b18_3_1m___2_5_x_0_45_x_10_hex_shcs____10nhx_2" />
        <child link="hex_nut_style_1_am_b18_2_4_1m___hex_nut__style_1___m2_5_x_0_45___d_n_3" />
    </joint>
    <joint name="fastened_45_0" type="fixed">
        <origin xyz="-0.022 -0.0181602 0.005" rpy="0 1.5708 -0" />
        <axis xyz="1 0 0" />
        <parent link="robot_belt_arm_socket_v2" />
        <child link="socket_head_cap_screw_am_b18_3_1m___3_x_0_5_x_10_hex_shcs____10nhx_6" />
    </joint>
    <joint name="fastened_46_0" type="fixed">
        <origin xyz="-0.022 -0.0491602 0.005" rpy="0 1.5708 -0" />
        <axis xyz="1 0 0" />
        <parent link="robot_belt_arm_socket_v2" />
        <child link="socket_head_cap_screw_am_b18_3_1m___3_x_0_5_x_10_hex_shcs____10nhx" />
    </joint>
    <joint name="fastened_47_0" type="fixed">
        <origin xyz="0.0097465 3.46945e-18 -2.77556e-17" rpy="0 -1.5708 3.14159" />
        <axis xyz="0 0 1" />
        <parent link="socket_head_cap_screw_am_b18_3_1m___2_5_x_0_45_x_10_hex_shcs____10nhx" />
        <child link="hex_nut_style_1_am_b18_2_4_1m___hex_nut__style_1___m2_5_x_0_45___d_n_1" />
    </joint>
    <joint name="fastened_48_0" type="fixed">
        <origin xyz="0.0097465 -3.46945e-18 -2.77556e-17" rpy="0 -1.5708 3.14159" />
        <axis xyz="0 0 -1" />
        <parent link="socket_head_cap_screw_am_b18_3_1m___2_5_x_0_45_x_10_hex_shcs____10nhx_4" />
        <child link="hex_nut_style_1_am_b18_2_4_1m___hex_nut__style_1___m2_5_x_0_45___d_n_2" />
    </joint>
    <joint name="fastened_49_0" type="fixed">
        <origin xyz="-0.174416 -0.0251722 2.77556e-17" rpy="0 -1.5708 3.14159" />
        <axis xyz="1 0 0" />
        <parent link="gripper_finger_washer___mymod" />
        <child link="socket_button_head_cap_screw_am_b18_3_4m___3_x_0_5_x_8_sbhcs___n_5" />
    </joint>
    <joint name="fastened_4_0" type="fixed">
        <origin xyz="-6.93889e-18 0.01834 0.036" rpy="0 -0 3.14159" />
        <axis xyz="1 0 0" />
        <parent link="robot_belt_arm_leg_2" />
        <child link="robot_belt_arm_socket_v2" />
    </joint>
    <joint name="fastened_50_0" type="fixed">
        <origin xyz="-0.174416 -0.0251722 -2.77556e-17" rpy="0 -1.5708 4.38178e-17" />
        <axis xyz="1 0 0" />
        <parent link="gripper_finger_washer___mymod_1" />
        <child link="socket_button_head_cap_screw_am_b18_3_4m___3_x_0_5_x_8_sbhcs___n_16" />
    </joint>
    <joint name="fastened_5_0" type="fixed">
        <origin xyz="2.77556e-17 0.0065 2.77556e-17" rpy="0 -1.5708 1.39786e-15" />
        <axis xyz="0 -1 0" />
        <parent link="robot_belt_arm_gear_body_1" />
        <child link="lower_shank_140" />
    </joint>
    <joint name="fastened_6_0" type="fixed">
        <origin xyz="0.021 0.023 0.0345" rpy="3.14159 1.11575e-15 -5.4956e-15" />
        <axis xyz="-1 0 0" />
        <parent link="robot_belt_arm_main_body_v2______mymod" />
        <child link="robot_belt_arm_stabilizer___logigate" />
    </joint>
    <joint name="fastened_7_0" type="fixed">
        <origin xyz="-0.0225 0.023 0.0385" rpy="-3.98519e-16 -2.34146e-17 3.35842e-15" />
        <axis xyz="1 0 0" />
        <parent link="robot_belt_arm_main_body_v2______mymod" />
        <child link="robot_belt_arm_endstop___mymod" />
    </joint>
    <joint name="fastened_8_0" type="fixed">
        <origin xyz="0.0119997 0.022 -0.027" rpy="0 -1.5708 3.14159" />
        <axis xyz="1 0 0" />
        <parent link="manipulator_dual" />
        <child link="socket_button_head_cap_screw_am_b18_3_4m___4_x_0_7_x_20_sbhcs___n_4" />
    </joint>
    <joint name="fastened_9_0" type="fixed">
        <origin xyz="0.0175 0.0008 -1.11022e-16" rpy="-3.14159 2.50042e-15 -1.5708" />
        <axis xyz="1 0 0" />
        <parent link="28byj_48_5v_stepper_motor" />
        <child link="socket_button_head_cap_screw_am_b18_3_4m___3_x_0_5_x_6_sbhcs___n_1" />
    </joint>
    <joint name="final_motor_fastened_joint_0" type="fixed">
        <origin xyz="0.199541 -0.0467529 -0.195348" rpy="7.61352e-15 3.4988e-15 -3.14159" />
        <axis xyz="0 0 1" />
        <parent link="gripperbase_by_ftobler" />
        <child link="gripperfinger_by_ftobler_1" />
    </joint>
    <joint name="final_motor_fastened_joint_1" type="fixed">
        <origin xyz="-0.145292 0.0466209 -0.195348" rpy="-2.52468e-16 5.33604e-16 -3.33068e-16" />
        <axis xyz="0 0 1" />
        <parent link="gripperbase_by_ftobler" />
        <child link="gripperfinger_by_ftobler" />
    </joint>
    <joint name="final_motor_fastened_joint_2" type="fixed">
        <origin xyz="-0.00527287 0.0177687 9.99485e-13" rpy="-1.01868e-15 -6.1282e-16 -0.0134012" />
        <axis xyz="0 0 1" />
        <parent link="gripper_fingers_link_wire" />
        <child link="gripper_fingers_link_wire_1" />
    </joint>
    <joint name="final_motor_fastened_joint_3" type="fixed">
        <origin xyz="0.175273 -0.041981 0.204848" rpy="1.5708 2.77556e-17 -0.348517" />
        <axis xyz="0 0 1" />
        <parent link="gripper_shaft" />
        <child link="28byj_48_5v_stepper_motor" />
    </joint>
    <joint name="final_motor_fastened_joint_4" type="fixed">
        <origin xyz="-0.34748 -0.0935381 -8.60423e-16" rpy="1.58602e-15 -6.62772e-15 -3.14159" />
        <axis xyz="0 0 1" />
        <parent link="gripper_finger_washer___mymod_1" />
        <child link="gripper_finger_washer___mymod" />
    </joint>
    <joint name="final_motor_fastened_joint_5" type="fixed">
        <origin xyz="0.350607 -0.0217646 0.189648" rpy="7.06858e-16 -5.31245e-14 -0.123995" />
        <axis xyz="0 0 1" />
        <parent link="gripperfinger_by_ftobler" />
        <child link="gripper_finger_washer___mymod_1" />
    </joint>
    <joint name="final_motor_fastened_joint_6" type="fixed">
        <origin xyz="0.0307288 -0.205348 -0.158644" rpy="0 -1.5708 -1.57351" />
        <axis xyz="0 0 1" />
        <parent link="28byj_48_5v_stepper_motor" />
        <child link="gripper_fingers_link_wire" />
    </joint>
    <joint name="final_motor_fastened_joint_7" type="fixed">
        <origin xyz="-0.20806 0.129344 -0.189148" rpy="-9.77076e-15 1.25539e-15 -1.09828" />
        <axis xyz="0 0 1" />
        <parent link="gripper_finger_washer___mymod" />
        <child link="gripper_shaft" />
    </joint>
    <joint name="fixed_node_to_root_joint_0" type="fixed">
        <origin xyz="-0.101239 0.049005 0.0677" rpy="0 0 0" />
        <axis xyz="0 0 1" />
        <parent link="root" />
        <child link="robot_belt_arm_basering" />
    </joint>
    <joint name="parallel_4_3" type="prismatic">
        <origin xyz="-0.02115 -0.03151 0.027" rpy="1.5708 -6.69813e-15 3.14159" />
        <axis xyz="0 1 0" />
        <parent link="robot_belt_arm_main_body_v2______mymod" />
        <child link="parallel_4_2" />
        <limit effort="1" velocity="1" lower="-10000" upper="10000" />
    </joint>
    <joint name="parallel_4_4" type="prismatic">
        <origin xyz="0 0 0" rpy="0 -0 0" />
        <axis xyz="0 0 1" />
        <parent link="parallel_4_2" />
        <child link="parallel_4_1" />
        <limit effort="1" velocity="1" lower="-10000" upper="10000" />
    </joint>
    <joint name="parallel_4_5" type="prismatic">
        <origin xyz="0 0 0" rpy="0 -0 0" />
        <axis xyz="1 0 0" />
        <parent link="parallel_4_1" />
        <child link="parallel_4_0" />
        <limit effort="1" velocity="1" lower="-10000" upper="10000" />
    </joint>
    <joint name="revolute_10_0" type="continuous">
        <origin xyz="3.8384e-08 0.0135 0.064" rpy="3.14159 0.232182 -1.3986e-15" />
        <axis xyz="0 1 0" />
        <parent link="robot_belt_arm_main_body_v2______mymod" />
        <child link="robot_belt_arm_gear_body" />
    </joint>
    <joint name="revolute_11_0" type="continuous">
        <origin xyz="2.60209e-18 -1.38778e-17 -2.77556e-17" rpy="-3.14159 -0.908726 -1.13289e-14" />
        <axis xyz="0 -1 0" />
        <parent link="robot_belt_arm_gear_body" />
        <child link="robot_belt_arm_lever___mymod" />
    </joint>
    <joint name="revolute_12_0" type="continuous">
        <origin xyz="-0.035954 -0.008 -0.0175303" rpy="1.5708 0.987621 -1.93546e-14" />
        <axis xyz="0 0 -1" />
        <parent link="robot_belt_arm_lever___mymod" />
        <child link="pleuel_140" />
    </joint>
    <joint name="revolute_13_0" type="continuous">
        <origin xyz="-0.102411 -2.58759e-08 0.0954575" rpy="-3.14159 -1.14393 3.14159" />
        <axis xyz="0 1 0" />
        <parent link="pleuel_bend_140" />
        <child link="robot_belt_arm_triplate" />
    </joint>
    <joint name="revolute_14_0" type="continuous">
        <origin xyz="0.102411 0.00500004 -0.0954576" rpy="1.07158 -3.33067e-15 1.5708" />
        <axis xyz="-1 0 0" />
        <parent link="pleuel_bend_140_mirrored_1" />
        <child link="f624zz_103" />
    </joint>
    <joint name="revolute_15_0" type="continuous">
        <origin xyz="0.045 0.0035 0.008" rpy="3.14159 1.43826 -1.14751e-14" />
        <axis xyz="0 -1 0" />
        <parent link="robot_belt_arm_triplate" />
        <child link="pleuel_bend_140_mirrored_1" />
    </joint>
    <joint name="revolute_16_0" type="continuous">
        <origin xyz="-0.139911 0.0205 -0.005" rpy="1.5708 -1.04593 3.14159" />
        <axis xyz="0 0 1" />
        <parent link="lower_shank_140" />
        <child link="upper_shank_140" />
    </joint>
    <joint name="revolute_18_0" type="continuous">
        <origin xyz="-0.102411 4.85723e-17 0.0954576" rpy="-3.14159 -1.14393 3.14159" />
        <axis xyz="0 -1 0" />
        <parent link="pleuel_bend_140_mirrored" />
        <child link="triplate_dual" />
    </joint>
    <joint name="revolute_19_0" type="continuous">
        <origin xyz="0.045 -0.0035 0.008" rpy="-3.14159 1.43826 0" />
        <axis xyz="0 1 0" />
        <parent link="triplate_dual" />
        <child link="pleuel_bend_140_1" />
    </joint>
    <joint name="revolute_1_0" type="continuous">
        <origin xyz="4.85723e-17 -0.0336603 0.0257" rpy="2.02624e-16 -4.55524e-17 0.559643" />
        <axis xyz="0 0 -1" />
        <parent link="robot_belt_arm_socket_v2" />
        <child link="robot_belt_arm_main_body_v2______mymod" />
    </joint>
    <joint name="revolute_22_0" type="continuous">
        <origin xyz="0.0119997 0.022 -0.021" rpy="1.94752e-15 -1.28355e-15 9.71452e-16" />
        <axis xyz="0 0 -1" />
        <parent link="manipulator_dual" />
        <child link="gripperbase_by_ftobler" />
    </joint>
    <joint name="revolute_23_0" type="continuous">
        <origin xyz="0.102411 -1.11022e-16 -0.0954576" rpy="-3.14159 1.43823 1.50858e-14" />
        <axis xyz="0 1 0" />
        <parent link="pleuel_bend_140_mirrored_1" />
        <child link="manipulator_dual" />
    </joint>
    <joint name="revolute_24_0" type="continuous">
        <origin xyz="0.03 0.0089 -0.012" rpy="-0.377448 2.52576e-15 -1.5708" />
        <axis xyz="-1 0 0" />
        <parent link="robot_belt_arm_triplate" />
        <child link="f686zz_83" />
    </joint>
    <joint name="revolute_25_0" type="continuous">
        <origin xyz="-0.11402 0.0812835 0.001" rpy="0 1.5708 0.311198" />
        <axis xyz="-1 0 0" />
        <parent link="pleuel_140" />
        <child link="f624zz_23" />
    </joint>
    <joint name="revolute_26_0" type="continuous">
        <origin xyz="5.55112e-17 0.00500004 5.55112e-17" rpy="-2.07001 1.11022e-16 1.5708" />
        <axis xyz="-1 0 0" />
        <parent link="pleuel_bend_140_mirrored_1" />
        <child link="f624zz_90" />
    </joint>
    <joint name="revolute_27_0" type="continuous">
        <origin xyz="5.55112e-17 -0.00500004 0" rpy="2.2706 -4.32987e-15 -1.5708" />
        <axis xyz="-1 0 0" />
        <parent link="pleuel_bend_140_1" />
        <child link="f624zz_34" />
    </joint>
    <joint name="revolute_28_0" type="continuous">
        <origin xyz="-0.102411 0.00500004 0.0954576" rpy="-2.15739 -3.60822e-15 1.5708" />
        <axis xyz="-1 0 0" />
        <parent link="pleuel_bend_140_mirrored" />
        <child link="f624zz_5" />
    </joint>
    <joint name="revolute_29_0" type="continuous">
        <origin xyz="-0.102411 -0.00500004 0.0954576" rpy="2.15739 6.10623e-16 -1.5708" />
        <axis xyz="-1 0 0" />
        <parent link="pleuel_bend_140" />
        <child link="f624zz_46" />
    </joint>
    <joint name="revolute_2_0" type="continuous">
        <origin xyz="5.55112e-17 1.73472e-16 3.33067e-16" rpy="-2.08079e-15 3.12771e-16 1.00352" />
        <axis xyz="0 0 -1" />
        <parent link="robot_belt_arm_main_body_v2______mymod" />
        <child link="robot_belt_arm_rotategear___mymod" />
    </joint>
    <joint name="revolute_30_0" type="continuous">
        <origin xyz="3.8384e-08 0.026 0.064" rpy="-1.5708 -1.44676e-15 6.57373e-15" />
        <axis xyz="0 0 -1" />
        <parent link="robot_belt_arm_main_body_v2______mymod" />
        <child link="prevailing_torque_hex_flange_nut_am_am_m6_n_1" />
    </joint>
    <joint name="revolute_31_0" type="continuous">
        <origin xyz="-0.03 0.026 0.076" rpy="-3.14159 1.14391 -3.14159" />
        <axis xyz="0 -1 0" />
        <parent link="robot_belt_arm_main_body_v2______mymod" />
        <child link="pleuel_bend_140_mirrored" />
    </joint>
    <joint name="revolute_32_0" type="continuous">
        <origin xyz="-0.03 -0.026 0.076" rpy="-3.14159 1.14391 -3.14159" />
        <axis xyz="0 1 0" />
        <parent link="robot_belt_arm_main_body_v2______mymod" />
        <child link="pleuel_bend_140" />
    </joint>
    <joint name="revolute_33_0" type="continuous">
        <origin xyz="-0.053 -0.0181602 0.005" rpy="0 1.5708 -0" />
        <axis xyz="1 0 0" />
        <parent link="robot_belt_arm_socket_v2" />
        <child link="socket_head_cap_screw_am_b18_3_1m___3_x_0_5_x_10_hex_shcs____10nhx_1" />
    </joint>
    <joint name="revolute_34_0" type="continuous">
        <origin xyz="-0.0104652 -0.031 0.031735" rpy="-3.28385e-15 -0.785398 8.31403e-15" />
        <axis xyz="0 -1 0" />
        <parent link="robot_belt_arm_endstop___mymod" />
        <child link="limit_switch_2" />
    </joint>
    <joint name="revolute_38_0" type="continuous">
        <origin xyz="-1.82146e-17 -0.0025 -0.01" rpy="3.44926e-14 1.99844e-15 1.5708" />
        <axis xyz="1 0 0" />
        <parent link="robot_belt_arm_gear_body" />
        <child link="socket_head_cap_screw_am_b18_3_1m___3_x_0_5_x_10_hex_shcs____10nhx_5" />
    </joint>
    <joint name="revolute_39_0" type="continuous">
        <origin xyz="-4.33681e-18 -0.0025 0.01" rpy="3.44926e-14 1.99844e-15 1.5708" />
        <axis xyz="1 0 0" />
        <parent link="robot_belt_arm_gear_body" />
        <child link="socket_head_cap_screw_am_b18_3_1m___3_x_0_5_x_10_hex_shcs____10nhx_3" />
    </joint>
    <joint name="revolute_3_0" type="continuous">
        <origin xyz="2.77556e-17 -0.00500004 4.16334e-17" rpy="2.15739 -4.44089e-16 -1.5708" />
        <axis xyz="-1 0 0" />
        <parent link="pleuel_bend_140" />
        <child link="f624zz_55" />
    </joint>
    <joint name="revolute_40_0" type="continuous">
        <origin xyz="-0.01 -0.0025 -2.77556e-17" rpy="-1.5708 -1.11022e-15 1.5708" />
        <axis xyz="1 0 0" />
        <parent link="robot_belt_arm_gear_body" />
        <child link="socket_head_cap_screw_am_b18_3_1m___3_x_0_5_x_10_hex_shcs____10nhx_2" />
    </joint>
    <joint name="revolute_41_0" type="continuous">
        <origin xyz="0.00999996 -0.0025 -2.77556e-17" rpy="3.44926e-14 1.99844e-15 1.5708" />
        <axis xyz="1 0 0" />
        <parent link="robot_belt_arm_gear_body" />
        <child link="socket_head_cap_screw_am_b18_3_1m___3_x_0_5_x_10_hex_shcs____10nhx_7" />
    </joint>
    <joint name="revolute_4_0" type="continuous">
        <origin xyz="-5.55112e-17 0.00500004 -4.16334e-17" rpy="-2.15739 -4.88498e-15 1.5708" />
        <axis xyz="-1 0 0" />
        <parent link="pleuel_bend_140_mirrored" />
        <child link="f624zz_78" />
    </joint>
    <joint name="revolute_5_0" type="continuous">
        <origin xyz="-0.015 0.0075 -0.02" rpy="3.32548e-07 1.99214e-15 1.5708" />
        <axis xyz="1 0 0" />
        <parent link="manipulator_dual" />
        <child link="socket_head_cap_screw_am_b18_3_1m___6_x_1_0_x_40_hex_shcs____24nhx" />
    </joint>
    <joint name="revolute_6_0" type="continuous">
        <origin xyz="-5.55112e-17 8.32667e-17 0.005" rpy="0 -1.5708 3.45279" />
        <axis xyz="-1 0 0" />
        <parent link="pleuel_140" />
        <child link="f624zz_14" />
    </joint>
    <joint name="revolute_8_0" type="continuous">
        <origin xyz="0.102411 -0.00500004 -0.0954576" rpy="-0.397052 -1.6348e-14 -1.5708" />
        <axis xyz="-1 0 0" />
        <parent link="pleuel_bend_140_1" />
        <child link="f624zz_73" />
    </joint>
    <joint name="revolute_9_0" type="continuous">
        <origin xyz="3.53185e-08 -0.02 0.064" rpy="3.14159 -1.21288 -3.14159" />
        <axis xyz="0 1 0" />
        <parent link="robot_belt_arm_main_body_v2______mymod" />
        <child link="robot_belt_arm_gear_body_1" />
    </joint>
</robot>