<?xml version='1.0' encoding='utf-8'?>
<robot name="complete_robotic_arm_assembly_with_dual_manipulator_140mm_shank">
    <link name="28byj_48_5v_stepper_motor">
        <inertial>
            <mass value="1.29383e-05" />
            <origin xyz="4.81215e-08 0.00903231 -0.000985167" rpy="0 -0 0" />
            <inertia ixx="1.21271e-09" ixy="-6.17404e-15" ixz="2.99318e-15" iyy="1.40051e-09" iyz="1.35666e-11" izz="1.03166e-09" />
        </inertial>
        <visual>
            <origin xyz="0 0 0" rpy="0 -0 0" />
            <geometry>
                <mesh filename="package://community_robot_arm/meshes/28byj_48_5v_stepper_motor.stl" scale="1 1 1" />
            </geometry>
            <material name="0.662745_0.686275_0.698039_0.000000_0.000000">
                <texture />
                <color rgba="0.662745 0.686275 0.698039 1" />
            </material>
        </visual>
    </link>
    <link name="f624zz_97">
        <inertial>
            <mass value="2.52711e-07" />
            <origin xyz="-0.00115244 4.71345e-19 2.39522e-19" rpy="0 -0 0" />
            <inertia ixx="9.55574e-12" ixy="0" ixz="0" iyy="5.35879e-12" iyz="0" izz="5.35879e-12" />
        </inertial>
        <visual>
            <origin xyz="-0.004 0 0" rpy="0 -0 0" />
            <geometry>
                <mesh filename="package://community_robot_arm/meshes/f624zz_97.stl" scale="1 1 1" />
            </geometry>
            <material name="0.792157_0.819608_0.933333_0.000000_0.000000">
                <texture />
                <color rgba="0.792157 0.819608 0.933333 1" />
            </material>
        </visual>
    </link>
    <link name="gripper_finger_washer___mymod">
        <inertial>
            <mass value="2.57418e-07" />
            <origin xyz="-0.174337 -0.0267358 0.001" rpy="0 -0 0" />
            <inertia ixx="4.39971e-12" ixy="7.29752e-14" ixz="0" iyy="2.49124e-12" iyz="0" izz="6.71933e-12" />
        </inertial>
        <visual>
            <origin xyz="0 0 0" rpy="0 -0 0" />
            <geometry>
                <mesh filename="package://community_robot_arm/meshes/gripper_finger_washer___mymod_1.stl" scale="1 1 1" />
            </geometry>
            <material name="0.909804_0.443137_0.031373_0.000000_0.000000">
                <texture />
                <color rgba="0.909804 0.443137 0.0313726 1" />
            </material>
        </visual>
    </link>
    <link name="gripper_finger_washer___mymod_1">
        <inertial>
            <mass value="2.57418e-07" />
            <origin xyz="-0.174337 -0.0267358 0.001" rpy="0 -0 0" />
            <inertia ixx="4.39971e-12" ixy="7.29752e-14" ixz="0" iyy="2.49124e-12" iyz="0" izz="6.71933e-12" />
        </inertial>
        <visual>
            <origin xyz="0 0 0" rpy="0 -0 0" />
            <geometry>
                <mesh filename="package://community_robot_arm/meshes/gripper_finger_washer___mymod_1.stl" scale="1 1 1" />
            </geometry>
            <material name="0.909804_0.443137_0.031373_0.000000_0.000000">
                <texture />
                <color rgba="0.909804 0.443137 0.0313726 1" />
            </material>
        </visual>
    </link>
    <link name="gripper_fingers_link_wire">
        <inertial>
            <mass value="5.2548e-08" />
            <origin xyz="0.169527 -0.0389644 0.194151" rpy="0 -0 0" />
            <inertia ixx="2.50352e-12" ixy="-1.25961e-12" ixz="0" iyy="7.7235e-13" iyz="0" izz="3.07149e-12" />
        </inertial>
        <visual>
            <origin xyz="0 0 0" rpy="0 -0 0" />
            <geometry>
                <mesh filename="package://community_robot_arm/meshes/gripper_fingers_link_wire_1.stl" scale="1 1 1" />
            </geometry>
            <material name="0.780392_0.760784_0.741176_0.000000_0.000000">
                <texture />
                <color rgba="0.780392 0.760784 0.741176 1" />
            </material>
        </visual>
    </link>
    <link name="gripper_fingers_link_wire_1">
        <inertial>
            <mass value="5.2548e-08" />
            <origin xyz="0.169527 -0.0389644 0.194151" rpy="0 -0 0" />
            <inertia ixx="2.50352e-12" ixy="-1.25961e-12" ixz="0" iyy="7.7235e-13" iyz="0" izz="3.07149e-12" />
        </inertial>
        <visual>
            <origin xyz="0 0 0" rpy="0 -0 0" />
            <geometry>
                <mesh filename="package://community_robot_arm/meshes/gripper_fingers_link_wire_1.stl" scale="1 1 1" />
            </geometry>
            <material name="0.780392_0.760784_0.741176_0.000000_0.000000">
                <texture />
                <color rgba="0.780392 0.760784 0.741176 1" />
            </material>
        </visual>
    </link>
    <link name="gripper_shaft">
        <inertial>
            <mass value="1.7657e-06" />
            <origin xyz="0.172541 -0.0495 0.198272" rpy="0 -0 0" />
            <inertia ixx="4.86296e-11" ixy="0" ixz="0" iyy="4.86296e-11" iyz="0" izz="7.95991e-11" />
        </inertial>
        <visual>
            <origin xyz="0 0 0" rpy="0 -0 0" />
            <geometry>
                <mesh filename="package://community_robot_arm/meshes/gripper_shaft.stl" scale="1 1 1" />
            </geometry>
            <material name="0.298039_0.298039_0.298039_0.000000_0.000000">
                <texture />
                <color rgba="0.298039 0.298039 0.298039 1" />
            </material>
        </visual>
    </link>
    <link name="gripperbase_by_ftobler">
        <inertial>
            <mass value="1.98957e-05" />
            <origin xyz="0.0185505 -2.74963e-12 0.00576395" rpy="0 -0 0" />
            <inertia ixx="5.56859e-09" ixy="0" ixz="-1.29708e-10" iyy="4.59113e-09" iyz="0" izz="9.8576e-09" />
        </inertial>
        <visual>
            <origin xyz="-0.145541 0.0495 -0.195348" rpy="0 -0 0" />
            <geometry>
                <mesh filename="package://community_robot_arm/meshes/gripperbase_by_ftobler.stl" scale="1 1 1" />
            </geometry>
            <material name="0.909804_0.443137_0.031373_0.000000_0.000000">
                <texture />
                <color rgba="0.909804 0.443137 0.0313726 1" />
            </material>
        </visual>
    </link>
    <link name="gripperfinger_by_ftobler">
        <inertial>
            <mass value="6.4034e-06" />
            <origin xyz="0.172227 -0.0306439 0.190577" rpy="0 -0 0" />
            <inertia ixx="8.20348e-10" ixy="2.31178e-12" ixz="1.54025e-12" iyy="5.89535e-10" iyz="-2.75788e-10" izz="8.30458e-10" />
        </inertial>
        <visual>
            <origin xyz="0 0 0" rpy="0 -0 0" />
            <geometry>
                <mesh filename="package://community_robot_arm/meshes/gripperfinger_by_ftobler_1.stl" scale="1 1 1" />
            </geometry>
            <material name="0.298039_0.298039_0.298039_0.000000_0.000000">
                <texture />
                <color rgba="0.298039 0.298039 0.298039 1" />
            </material>
        </visual>
    </link>
    <link name="gripperfinger_by_ftobler_1">
        <inertial>
            <mass value="6.4034e-06" />
            <origin xyz="0.172227 -0.0306439 0.190577" rpy="0 -0 0" />
            <inertia ixx="8.20348e-10" ixy="2.31178e-12" ixz="1.54025e-12" iyy="5.89535e-10" iyz="-2.75788e-10" izz="8.30458e-10" />
        </inertial>
        <visual>
            <origin xyz="0 0 0" rpy="0 -0 0" />
            <geometry>
                <mesh filename="package://community_robot_arm/meshes/gripperfinger_by_ftobler_1.stl" scale="1 1 1" />
            </geometry>
            <material name="0.298039_0.298039_0.298039_0.000000_0.000000">
                <texture />
                <color rgba="0.298039 0.298039 0.298039 1" />
            </material>
        </visual>
    </link>
    <link name="lower_shank_140">
        <inertial>
            <mass value="4.07717e-05" />
            <origin xyz="-0.0614049 0.0102085 -0.00216941" rpy="0 -0 0" />
            <inertia ixx="4.27132e-09" ixy="1.75967e-09" ixz="-3.25931e-09" iyy="9.56728e-08" iyz="6.22103e-11" izz="9.64503e-08" />
        </inertial>
        <visual>
            <origin xyz="-0.117686 0.659005 -0.110224" rpy="0 -0 0" />
            <geometry>
                <mesh filename="package://community_robot_arm/meshes/lower_shank_140.stl" scale="1 1 1" />
            </geometry>
            <material name="0.909804_0.443137_0.031373_0.000000_0.000000">
                <texture />
                <color rgba="0.909804 0.443137 0.0313726 1" />
            </material>
        </visual>
    </link>
    <link name="manipulator_dual">
        <inertial>
            <mass value="1.86105e-05" />
            <origin xyz="0.0114384 0.00750006 0.00405812" rpy="0 -0 0" />
            <inertia ixx="5.21773e-09" ixy="3.20908e-15" ixz="3.12277e-10" iyy="3.64946e-09" iyz="-4.73798e-15" izz="6.02391e-09" />
        </inertial>
        <visual>
            <origin xyz="-0.182858 0.524005 -0.198759" rpy="0 -0 0" />
            <geometry>
                <mesh filename="package://community_robot_arm/meshes/manipulator_dual.stl" scale="1 1 1" />
            </geometry>
            <material name="0.298039_0.298039_0.298039_0.000000_0.000000">
                <texture />
                <color rgba="0.298039 0.298039 0.298039 1" />
            </material>
        </visual>
    </link>
    <link name="pleuel_140">
        <inertial>
            <mass value="8.66732e-06" />
            <origin xyz="-0.0570102 0.0406136 0.00275546" rpy="0 -0 0" />
            <inertia ixx="6.81312e-09" ixy="9.33524e-09" ixz="4.14189e-11" iyy="1.32694e-08" iyz="-2.95172e-11" izz="2.00339e-08" />
        </inertial>
        <visual>
            <origin xyz="-0.0246033 0.560849 0" rpy="0 -0 0" />
            <geometry>
                <mesh filename="package://community_robot_arm/meshes/pleuel_140.stl" scale="1 1 1" />
            </geometry>
            <material name="0.298039_0.298039_0.298039_0.000000_0.000000">
                <texture />
                <color rgba="0.298039 0.298039 0.298039 1" />
            </material>
        </visual>
    </link>
    <link name="pleuel_bend_140">
        <inertial>
            <mass value="8.88371e-06" />
            <origin xyz="0.0471859 -0.00267208 -0.0507506" rpy="0 -0 0" />
            <inertia ixx="9.12195e-09" ixy="8.52545e-13" ixz="1.00708e-08" iyy="2.08688e-08" iyz="6.40815e-13" izz="1.17958e-08" />
        </inertial>
        <visual>
            <origin xyz="-0.0270684 0.541505 -0.149475" rpy="0 -0 0" />
            <geometry>
                <mesh filename="package://community_robot_arm/meshes/pleuel_bend_140_1.stl" scale="1 1 1" />
            </geometry>
            <material name="0.909804_0.443137_0.031373_0.000000_0.000000">
                <texture />
                <color rgba="0.909804 0.443137 0.0313726 1" />
            </material>
        </visual>
    </link>
    <link name="pleuel_bend_140_1">
        <inertial>
            <mass value="8.88371e-06" />
            <origin xyz="0.0471859 -0.00267208 -0.0507506" rpy="0 -0 0" />
            <inertia ixx="9.12195e-09" ixy="8.52545e-13" ixz="1.00708e-08" iyy="2.08688e-08" iyz="6.40815e-13" izz="1.17958e-08" />
        </inertial>
        <visual>
            <origin xyz="-0.0270684 0.541505 -0.149475" rpy="0 -0 0" />
            <geometry>
                <mesh filename="package://community_robot_arm/meshes/pleuel_bend_140_1.stl" scale="1 1 1" />
            </geometry>
            <material name="0.909804_0.443137_0.031373_0.000000_0.000000">
                <texture />
                <color rgba="0.909804 0.443137 0.0313726 1" />
            </material>
        </visual>
    </link>
    <link name="pleuel_bend_140_mirrored">
        <inertial>
            <mass value="8.88371e-06" />
            <origin xyz="0.0471859 0.00267208 -0.0507506" rpy="0 -0 0" />
            <inertia ixx="9.12195e-09" ixy="-8.5254e-13" ixz="1.00708e-08" iyy="2.08688e-08" iyz="-6.40819e-13" izz="1.17958e-08" />
        </inertial>
        <visual>
            <origin xyz="-0.0270684 0.541505 -0.149475" rpy="0 -0 0" />
            <geometry>
                <mesh filename="package://community_robot_arm/meshes/pleuel_bend_140_mirrored_1.stl" scale="1 1 1" />
            </geometry>
            <material name="0.909804_0.443137_0.031373_0.000000_0.000000">
                <texture />
                <color rgba="0.909804 0.443137 0.0313726 1" />
            </material>
        </visual>
    </link>
    <link name="pleuel_bend_140_mirrored_1">
        <inertial>
            <mass value="8.88371e-06" />
            <origin xyz="0.0471859 0.00267208 -0.0507506" rpy="0 -0 0" />
            <inertia ixx="9.12195e-09" ixy="-8.5254e-13" ixz="1.00708e-08" iyy="2.08688e-08" iyz="-6.40819e-13" izz="1.17958e-08" />
        </inertial>
        <visual>
            <origin xyz="-0.0270684 0.541505 -0.149475" rpy="0 -0 0" />
            <geometry>
                <mesh filename="package://community_robot_arm/meshes/pleuel_bend_140_mirrored_1.stl" scale="1 1 1" />
            </geometry>
            <material name="0.909804_0.443137_0.031373_0.000000_0.000000">
                <texture />
                <color rgba="0.909804 0.443137 0.0313726 1" />
            </material>
        </visual>
    </link>
    <link name="robot_belt_arm_basering">
        <inertial>
            <mass value="1.01419e-05" />
            <origin xyz="0.103846 -0.0490051 -0.0655056" rpy="0 -0 0" />
            <inertia ixx="1.2594e-08" ixy="0" ixz="-6.1665e-11" iyy="1.05985e-08" iyz="0" izz="2.31591e-08" />
        </inertial>
        <visual>
            <origin xyz="0 0 0" rpy="0 -0 0" />
            <geometry>
                <mesh filename="package://community_robot_arm/meshes/robot_belt_arm_basering.stl" scale="1 1 1" />
            </geometry>
            <material name="0.909804_0.443137_0.031373_0.000000_0.000000">
                <texture />
                <color rgba="0.909804 0.443137 0.0313726 1" />
            </material>
        </visual>
    </link>
    <link name="robot_belt_arm_endstop___mymod">
        <inertial>
            <mass value="4.31512e-06" />
            <origin xyz="-0.00486144 -0.0279785 0.00347698" rpy="0 -0 0" />
            <inertia ixx="1.20814e-09" ixy="-3.2158e-11" ixz="9.90297e-11" iyy="6.39665e-10" iyz="1.39582e-10" izz="6.92063e-10" />
        </inertial>
        <visual>
            <origin xyz="-0.0774887 0.0260051 -0.037" rpy="0 -0 0" />
            <geometry>
                <mesh filename="package://community_robot_arm/meshes/robot_belt_arm_endstop___mymod.stl" scale="1 1 1" />
            </geometry>
            <material name="0.298039_0.298039_0.298039_0.000000_0.000000">
                <texture />
                <color rgba="0.298039 0.298039 0.298039 1" />
            </material>
        </visual>
    </link>
    <link name="robot_belt_arm_gear_body">
        <inertial>
            <mass value="1.12002e-05" />
            <origin xyz="9.98615e-10 -0.00319577 2.52749e-09" rpy="0 -0 0" />
            <inertia ixx="2.60723e-09" ixy="0" ixz="0" iyy="5.13533e-09" iyz="0" izz="2.60723e-09" />
        </inertial>
        <visual>
            <origin xyz="-0.0999999 0.0625 -0.0625" rpy="0 -0 0" />
            <geometry>
                <mesh filename="package://community_robot_arm/meshes/robot_belt_arm_gear_body_1.stl" scale="1 1 1" />
            </geometry>
            <material name="0.298039_0.298039_0.298039_0.000000_0.000000">
                <texture />
                <color rgba="0.298039 0.298039 0.298039 1" />
            </material>
        </visual>
    </link>
    <link name="robot_belt_arm_gear_body_1">
        <inertial>
            <mass value="1.12002e-05" />
            <origin xyz="9.98615e-10 0.00330423 2.52749e-09" rpy="0 -0 0" />
            <inertia ixx="2.60723e-09" ixy="0" ixz="0" iyy="5.13533e-09" iyz="0" izz="2.60723e-09" />
        </inertial>
        <visual>
            <origin xyz="-0.0999999 0.069 -0.0625" rpy="0 -0 0" />
            <geometry>
                <mesh filename="package://community_robot_arm/meshes/robot_belt_arm_gear_body_1.stl" scale="1 1 1" />
            </geometry>
            <material name="0.298039_0.298039_0.298039_0.000000_0.000000">
                <texture />
                <color rgba="0.298039 0.298039 0.298039 1" />
            </material>
        </visual>
    </link>
    <link name="robot_belt_arm_leg">
        <inertial>
            <mass value="1.42189e-05" />
            <origin xyz="8.15356e-12 0.0152179 0.0190616" rpy="0 -0 0" />
            <inertia ixx="2.39223e-09" ixy="0" ixz="0" iyy="3.2551e-09" iyz="-9.64423e-10" izz="2.33108e-09" />
        </inertial>
        <visual>
            <origin xyz="-0.0999887 0.101005 0.0632" rpy="0 -0 0" />
            <geometry>
                <mesh filename="package://community_robot_arm/meshes/robot_belt_arm_leg_2.stl" scale="1 1 1" />
            </geometry>
            <material name="0.298039_0.298039_0.298039_0.000000_0.000000">
                <texture />
                <color rgba="0.298039 0.298039 0.298039 1" />
            </material>
        </visual>
    </link>
    <link name="robot_belt_arm_leg_1">
        <inertial>
            <mass value="1.42189e-05" />
            <origin xyz="8.15356e-12 0.0152179 0.0190616" rpy="0 -0 0" />
            <inertia ixx="2.39223e-09" ixy="0" ixz="0" iyy="3.2551e-09" iyz="-9.64423e-10" izz="2.33108e-09" />
        </inertial>
        <visual>
            <origin xyz="-0.0999887 0.101005 0.0632" rpy="0 -0 0" />
            <geometry>
                <mesh filename="package://community_robot_arm/meshes/robot_belt_arm_leg_2.stl" scale="1 1 1" />
            </geometry>
            <material name="0.298039_0.298039_0.298039_0.000000_0.000000">
                <texture />
                <color rgba="0.298039 0.298039 0.298039 1" />
            </material>
        </visual>
    </link>
    <link name="robot_belt_arm_leg_2">
        <inertial>
            <mass value="1.42189e-05" />
            <origin xyz="8.15356e-12 0.0152179 0.0190616" rpy="0 -0 0" />
            <inertia ixx="2.39223e-09" ixy="0" ixz="0" iyy="3.2551e-09" iyz="-9.64423e-10" izz="2.33108e-09" />
        </inertial>
        <visual>
            <origin xyz="-0.0999887 0.101005 0.0632" rpy="0 -0 0" />
            <geometry>
                <mesh filename="package://community_robot_arm/meshes/robot_belt_arm_leg_2.stl" scale="1 1 1" />
            </geometry>
            <material name="0.298039_0.298039_0.298039_0.000000_0.000000">
                <texture />
                <color rgba="0.298039 0.298039 0.298039 1" />
            </material>
        </visual>
    </link>
    <link name="robot_belt_arm_lever___mymod">
        <inertial>
            <mass value="1.00295e-05" />
            <origin xyz="-0.0129468 -0.00400119 -0.00683616" rpy="0 -0 0" />
            <inertia ixx="1.09738e-09" ixy="1.55157e-13" ixz="-8.41221e-10" iyy="3.28828e-09" iyz="8.19259e-14" izz="2.29642e-09" />
        </inertial>
        <visual>
            <origin xyz="-0.1 0.0355 -0.0625" rpy="0 -0 0" />
            <geometry>
                <mesh filename="package://community_robot_arm/meshes/robot_belt_arm_lever___mymod.stl" scale="1 1 1" />
            </geometry>
            <material name="0.909804_0.443137_0.031373_0.000000_0.000000">
                <texture />
                <color rgba="0.909804 0.443137 0.0313726 1" />
            </material>
        </visual>
    </link>
    <link name="robot_belt_arm_main_body_v2______mymod">
        <inertial>
            <mass value="4.47417e-05" />
            <origin xyz="-0.00169715 -8.18852e-08 0.0312764" rpy="0 -0 0" />
            <inertia ixx="5.09789e-08" ixy="1.11364e-13" ixz="5.69671e-09" iyy="4.24137e-08" iyz="-9.27109e-14" izz="3.03074e-08" />
        </inertial>
        <visual>
            <origin xyz="-0.0999887 0.0490051 0.0015" rpy="0 -0 0" />
            <geometry>
                <mesh filename="package://community_robot_arm/meshes/robot_belt_arm_main_body_v2______mymod.stl" scale="1 1 1" />
            </geometry>
            <material name="0.909804_0.443137_0.031373_0.000000_0.000000">
                <texture />
                <color rgba="0.909804 0.443137 0.0313726 1" />
            </material>
        </visual>
    </link>
    <link name="robot_belt_arm_rotategear___mymod">
        <inertial>
            <mass value="1.60564e-05" />
            <origin xyz="-1.55585e-05 1.59387e-05 -0.00412005" rpy="0 -0 0" />
            <inertia ixx="3.9102e-09" ixy="3.71464e-14" ixz="-4.55715e-13" iyy="3.90519e-09" iyz="2.24593e-13" izz="7.57541e-09" />
        </inertial>
        <visual>
            <origin xyz="-0.0999887 0.0490051 0.0015" rpy="0 -0 0" />
            <geometry>
                <mesh filename="package://community_robot_arm/meshes/robot_belt_arm_rotategear___mymod.stl" scale="1 1 1" />
            </geometry>
            <material name="0.298039_0.298039_0.298039_0.000000_0.000000">
                <texture />
                <color rgba="0.298039 0.298039 0.298039 1" />
            </material>
        </visual>
    </link>
    <link name="robot_belt_arm_socket_v2">
        <inertial>
            <mass value="4.17145e-05" />
            <origin xyz="-0.00419504 -0.0353654 0.00537763" rpy="0 -0 0" />
            <inertia ixx="1.46523e-08" ixy="-2.12323e-09" ixz="-3.80484e-10" iyy="2.12835e-08" iyz="2.53443e-10" izz="3.46136e-08" />
        </inertial>
        <visual>
            <origin xyz="-0.0999887 0.0153449 0.0272" rpy="0 -0 0" />
            <geometry>
                <mesh filename="package://community_robot_arm/meshes/robot_belt_arm_socket_v2.stl" scale="1 1 1" />
            </geometry>
            <material name="0.909804_0.443137_0.031373_0.000000_0.000000">
                <texture />
                <color rgba="0.909804 0.443137 0.0313726 1" />
            </material>
        </visual>
    </link>
    <link name="robot_belt_arm_stabilizer___logigate">
        <inertial>
            <mass value="2.08009e-06" />
            <origin xyz="0.00169962 0.0230197 0.00496639" rpy="0 -0 0" />
            <inertia ixx="5.55096e-10" ixy="-8.40035e-14" ixz="1.43362e-13" iyy="3.43136e-11" iyz="-1.86001e-13" izz="5.25398e-10" />
        </inertial>
        <visual>
            <origin xyz="-0.120989 0.0720051 -0.023" rpy="0 -0 0" />
            <geometry>
                <mesh filename="package://community_robot_arm/meshes/robot_belt_arm_stabilizer___logigate.stl" scale="1 1 1" />
            </geometry>
            <material name="0.298039_0.298039_0.298039_0.000000_0.000000">
                <texture />
                <color rgba="0.298039 0.298039 0.298039 1" />
            </material>
        </visual>
    </link>
    <link name="robot_belt_arm_triplate">
        <inertial>
            <mass value="7.1204e-06" />
            <origin xyz="-0.00751201 -0.0032983 0.0123093" rpy="0 -0 0" />
            <inertia ixx="5.28717e-10" ixy="-6.15682e-11" ixz="1.71862e-11" iyy="1.966e-09" iyz="4.74273e-12" izz="1.50043e-09" />
        </inertial>
        <visual>
            <origin xyz="-0.0116852 0.0655 -0.143744" rpy="0 -0 0" />
            <geometry>
                <mesh filename="package://community_robot_arm/meshes/robot_belt_arm_triplate.stl" scale="1 1 1" />
            </geometry>
            <material name="0.298039_0.298039_0.298039_0.000000_0.000000">
                <texture />
                <color rgba="0.298039 0.298039 0.298039 1" />
            </material>
        </visual>
    </link>
    <link name="root">
        </link>
    <link name="triplate_dual">
        <inertial>
            <mass value="7.80508e-06" />
            <origin xyz="-0.00826499 0.00376765 0.0123589" rpy="0 -0 0" />
            <inertia ixx="5.71119e-10" ixy="1.10667e-10" ixz="1.2085e-11" iyy="2.19048e-09" iyz="-5.19697e-12" izz="1.72559e-09" />
        </inertial>
        <visual>
            <origin xyz="-0.0116852 0.0655 -0.143744" rpy="0 -0 0" />
            <geometry>
                <mesh filename="package://community_robot_arm/meshes/triplate_dual.stl" scale="1 1 1" />
            </geometry>
            <material name="0.298039_0.298039_0.298039_0.000000_0.000000">
                <texture />
                <color rgba="0.298039 0.298039 0.298039 1" />
            </material>
        </visual>
    </link>
    <link name="upper_shank_140">
        <inertial>
            <mass value="2.63723e-05" />
            <origin xyz="0.0509536 -1.83701e-05 -0.00798866" rpy="0 -0 0" />
            <inertia ixx="1.29113e-09" ixy="-7.99265e-12" ixz="-1.00146e-09" iyy="7.94528e-08" iyz="2.36742e-13" izz="7.97893e-08" />
        </inertial>
        <visual>
            <origin xyz="-0.05 0.23 -0.015" rpy="0 -0 0" />
            <geometry>
                <mesh filename="package://community_robot_arm/meshes/upper_shank_140.stl" scale="1 1 1" />
            </geometry>
            <material name="0.909804_0.443137_0.031373_0.000000_0.000000">
                <texture />
                <color rgba="0.909804 0.443137 0.0313726 1" />
            </material>
        </visual>
    </link>
    <joint name="fastened_1_0" type="fixed">
        <origin xyz="0.0999887 -0.101005 -0.0632" rpy="0 -0 0" />
        <axis xyz="1 0 0" />
        <parent link="robot_belt_arm_basering" />
        <child link="robot_belt_arm_leg" />
    </joint>
    <joint name="fastened_2_0" type="fixed">
        <origin xyz="0.151989 -0.0490051 -0.0632" rpy="0 -0 1.5708" />
        <axis xyz="1 0 0" />
        <parent link="robot_belt_arm_basering" />
        <child link="robot_belt_arm_leg_1" />
    </joint>
    <joint name="fastened_3_0" type="fixed">
        <origin xyz="0.0999887 0.00299489 -0.0632" rpy="0 -0 3.14159" />
        <axis xyz="1 0 0" />
        <parent link="robot_belt_arm_basering" />
        <child link="robot_belt_arm_leg_2" />
    </joint>
    <joint name="fastened_4_0" type="fixed">
        <origin xyz="0 0.01834 0.036" rpy="0 -0 3.14159" />
        <axis xyz="1 0 0" />
        <parent link="robot_belt_arm_leg_2" />
        <child link="robot_belt_arm_socket_v2" />
    </joint>
    <joint name="fastened_5_0" type="fixed">
        <origin xyz="-2.77556e-17 0.0065 5.55112e-17" rpy="0 -1.5708 -6.2421e-16" />
        <axis xyz="0 -1 0" />
        <parent link="robot_belt_arm_gear_body_1" />
        <child link="lower_shank_140" />
    </joint>
    <joint name="fastened_6_0" type="fixed">
        <origin xyz="0.021 0.023 0.0345" rpy="3.14159 1.11575e-15 -6.95971e-15" />
        <axis xyz="-1 0 0" />
        <parent link="robot_belt_arm_main_body_v2______mymod" />
        <child link="robot_belt_arm_stabilizer___logigate" />
    </joint>
    <joint name="fastened_7_0" type="fixed">
        <origin xyz="-0.0225 0.023 0.0385" rpy="-3.98519e-16 -2.34135e-17 5.21805e-15" />
        <axis xyz="1 0 0" />
        <parent link="robot_belt_arm_main_body_v2______mymod" />
        <child link="robot_belt_arm_endstop___mymod" />
    </joint>
    <joint name="final_motor_fastened_joint_0" type="fixed">
        <origin xyz="0.199541 -0.0467529 -0.195348" rpy="7.61135e-15 3.49775e-15 -3.14159" />
        <axis xyz="0 0 1" />
        <parent link="gripperbase_by_ftobler" />
        <child link="gripperfinger_by_ftobler_1" />
    </joint>
    <joint name="final_motor_fastened_joint_1" type="fixed">
        <origin xyz="-0.145292 0.0466209 -0.195348" rpy="-2.51811e-16 5.27346e-16 3.81627e-16" />
        <axis xyz="0 0 1" />
        <parent link="gripperbase_by_ftobler" />
        <child link="gripperfinger_by_ftobler" />
    </joint>
    <joint name="final_motor_fastened_joint_2" type="fixed">
        <origin xyz="-0.00527287 0.0177687 9.99485e-13" rpy="-1.01688e-15 -6.15966e-16 -0.0134012" />
        <axis xyz="0 0 1" />
        <parent link="gripper_fingers_link_wire" />
        <child link="gripper_fingers_link_wire_1" />
    </joint>
    <joint name="final_motor_fastened_joint_3" type="fixed">
        <origin xyz="0.175273 -0.041981 0.204848" rpy="1.5708 -1.44329e-15 -0.348517" />
        <axis xyz="0 0 1" />
        <parent link="gripper_shaft" />
        <child link="28byj_48_5v_stepper_motor" />
    </joint>
    <joint name="final_motor_fastened_joint_4" type="fixed">
        <origin xyz="-0.34748 -0.0935381 -4.71845e-16" rpy="1.59044e-15 -6.6229e-15 -3.14159" />
        <axis xyz="0 0 1" />
        <parent link="gripper_finger_washer___mymod_1" />
        <child link="gripper_finger_washer___mymod" />
    </joint>
    <joint name="final_motor_fastened_joint_5" type="fixed">
        <origin xyz="0.350607 -0.0217646 0.189648" rpy="7.09546e-16 -5.31213e-14 -0.123995" />
        <axis xyz="0 0 1" />
        <parent link="gripperfinger_by_ftobler" />
        <child link="gripper_finger_washer___mymod_1" />
    </joint>
    <joint name="final_motor_fastened_joint_6" type="fixed">
        <origin xyz="0.0307288 -0.205348 -0.158644" rpy="0 -1.5708 -1.57351" />
        <axis xyz="0 0 1" />
        <parent link="28byj_48_5v_stepper_motor" />
        <child link="gripper_fingers_link_wire" />
    </joint>
    <joint name="final_motor_fastened_joint_7" type="fixed">
        <origin xyz="-0.20806 0.129344 -0.189148" rpy="-9.76842e-15 1.25299e-15 -1.09828" />
        <axis xyz="0 0 1" />
        <parent link="gripper_finger_washer___mymod" />
        <child link="gripper_shaft" />
    </joint>
    <joint name="fixed_node_to_root_joint_0" type="fixed">
        <origin xyz="-0.0604648 0.0900997 0.153201" rpy="0 -0 0" />
        <axis xyz="0 0 1" />
        <parent link="root" />
        <child link="robot_belt_arm_basering" />
    </joint>
    <joint name="revolute_10_0" type="continuous">
        <origin xyz="3.8384e-08 0.0135 0.064" rpy="0 -1.5708 3.14159" />
        <axis xyz="0 1 0" />
        <parent link="robot_belt_arm_main_body_v2______mymod" />
        <child link="robot_belt_arm_gear_body" />
    </joint>
    <joint name="revolute_11_0" type="continuous">
        <origin xyz="2.77556e-17 0 6.93889e-18" rpy="4.3064e-16 -0.127314 -3.14159" />
        <axis xyz="0 -1 0" />
        <parent link="robot_belt_arm_gear_body" />
        <child link="robot_belt_arm_lever___mymod" />
    </joint>
    <joint name="revolute_12_0" type="continuous">
        <origin xyz="-0.035954 -0.008 -0.0175303" rpy="1.5708 -0.0168583 -7.47425e-15" />
        <axis xyz="0 0 -1" />
        <parent link="robot_belt_arm_lever___mymod" />
        <child link="pleuel_140" />
    </joint>
    <joint name="revolute_13_0" type="continuous">
        <origin xyz="-0.03 -0.0095 0.012" rpy="1.89172e-14 1.29555 8.81648e-15" />
        <axis xyz="0 1 0" />
        <parent link="robot_belt_arm_triplate" />
        <child link="pleuel_bend_140" />
    </joint>
    <joint name="revolute_15_0" type="continuous">
        <origin xyz="0.015 -0.006 0.02" rpy="1.11265e-14 1.40074 -3.14159" />
        <axis xyz="0 -1 0" />
        <parent link="robot_belt_arm_triplate" />
        <child link="pleuel_bend_140_mirrored_1" />
    </joint>
    <joint name="revolute_16_0" type="continuous">
        <origin xyz="-0.139911 0.0205 -0.00500004" rpy="-1.5708 -1.09096 -1.26261e-14" />
        <axis xyz="0 0 1" />
        <parent link="lower_shank_140" />
        <child link="upper_shank_140" />
    </joint>
    <joint name="revolute_17_0" type="continuous">
        <origin xyz="-0.139911 0.0275 -0.005" rpy="-3.14159 -1.06005 3.14159" />
        <axis xyz="0 -1 0" />
        <parent link="lower_shank_140" />
        <child link="triplate_dual" />
    </joint>
    <joint name="revolute_18_0" type="continuous">
        <origin xyz="-0.03 0.012 0.012" rpy="-1.00484e-14 1.29555 -5.92e-15" />
        <axis xyz="0 -1 0" />
        <parent link="triplate_dual" />
        <child link="pleuel_bend_140_mirrored" />
    </joint>
    <joint name="revolute_19_0" type="continuous">
        <origin xyz="0.015 0.0065 0.02" rpy="-2.27895e-14 1.40074 3.14159" />
        <axis xyz="0 1 0" />
        <parent link="triplate_dual" />
        <child link="pleuel_bend_140_1" />
    </joint>
    <joint name="revolute_1_0" type="continuous">
        <origin xyz="6.93889e-18 -0.0336603 0.0257" rpy="2.09752e-16 -1.6689e-16 1.46153" />
        <axis xyz="0 0 -1" />
        <parent link="robot_belt_arm_socket_v2" />
        <child link="robot_belt_arm_main_body_v2______mymod" />
    </joint>
    <joint name="revolute_21_0" type="continuous">
        <origin xyz="0.14 -1.29296e-09 -0.015" rpy="1.5708 -1.9984e-15 -0.990552" />
        <axis xyz="0 -1 0" />
        <parent link="upper_shank_140" />
        <child link="manipulator_dual" />
    </joint>
    <joint name="revolute_22_0" type="continuous">
        <origin xyz="0.0269997 0.00750003 -0.001" rpy="9.19543e-17 -1.04873e-16 5.41189e-16" />
        <axis xyz="0 0 -1" />
        <parent link="manipulator_dual" />
        <child link="gripperbase_by_ftobler" />
    </joint>
    <joint name="revolute_2_0" type="continuous">
        <origin xyz="1.38778e-17 6.93889e-18 0" rpy="1.80866e-16 -2.08813e-16 -1.46153" />
        <axis xyz="0 0 -1" />
        <parent link="robot_belt_arm_main_body_v2______mymod" />
        <child link="robot_belt_arm_rotategear___mymod" />
    </joint>
    <joint name="revolute_3_0" type="continuous">
        <origin xyz="0.102411 -0.00500004 -0.0954576" rpy="1.5708 -0 -1.5708" />
        <axis xyz="-1 0 0" />
        <parent link="pleuel_bend_140" />
        <child link="f624zz_97" />
    </joint>
    <joint name="revolute_7_0" type="continuous">
        <origin xyz="-0.139911 -0.003 -0.005" rpy="-3.14159 -1.06005 3.14159" />
        <axis xyz="0 1 0" />
        <parent link="lower_shank_140" />
        <child link="robot_belt_arm_triplate" />
    </joint>
    <joint name="revolute_9_0" type="continuous">
        <origin xyz="3.8384e-08 -0.02 0.064" rpy="-3.14159 -0.510761 3.14159" />
        <axis xyz="0 1 0" />
        <parent link="robot_belt_arm_main_body_v2______mymod" />
        <child link="robot_belt_arm_gear_body_1" />
    </joint>
</robot>